Workbook
Name CursePool1: 'Relic Cacul Temp'!$U:$U
Name CursePool2: 'Relic Cacul Temp'!$X:$X
Name CursePool3: 'Relic Cacul Temp'!$AA:$AA
Name EffectPool1: 'Relic Cacul Temp'!$L:$L
Name EffectPool2: 'Relic Cacul Temp'!$O:$O
Name EffectPool3: 'Relic Cacul Temp'!$R:$R
Name EmptyID: Variable!$H$2
Name LanguageList: 'UI Language'!$1:$1

Sheet UI
A1: =HLOOKUP($B$1,Tbl_Language[#All],MATCH("Language",Tbl_Language[English],0)+1,FALSE) -> 語言 | B1: 繁體中文
A2: =HLOOKUP($B$1,Tbl_Language[#All],MATCH("Relic",Tbl_Language[English],0)+1,FALSE) -> 遺物 | B2: 229-遼闊的幽靜情景 (綠) | D2: ID | E2: Sort ID(Override ID)
A3: =HLOOKUP($B$1,Tbl_Language[#All],MATCH("AttachEffect 1",Tbl_Language[English],0)+1,FALSE) -> 效果1 | B3: 7000202-耐力＋３ | D3: {=IF(B3<>"",_xlfn.CHOOSECOLS(_xlfn.TEXTSPLIT(B3,"-"),1),EmptyID)} -> 7000202 | E3: {=IF(D3<>EmptyID,VLOOKUP(VALUE(_xlfn.CHOOSECOLS(_xlfn.TEXTSPLIT(B3,"-"),1)),Tbl_Effect[],MATCH("overrideEffectId",Tbl_Effect[#Headers],0),FALSE),9999999999999)} -> 1000
A4: =HLOOKUP($B$1,Tbl_Language[#All],MATCH("AttachEffect 2",Tbl_Language[English],0)+1,FALSE) -> 效果2 | B4: 7342400-以弓攻擊時，恢復ＨＰ | D4: {=IF(B4<>"",_xlfn.CHOOSECOLS(_xlfn.TEXTSPLIT(B4,"-"),1),EmptyID)} -> 7342400 | E4: {=IF(D4<>EmptyID,VLOOKUP(VALUE(_xlfn.CHOOSECOLS(_xlfn.TEXTSPLIT(B4,"-"),1)),Tbl_Effect[],MATCH("overrideEffectId",Tbl_Effect[#Headers],0),FALSE),9999999999999)} -> 10
A5: =HLOOKUP($B$1,Tbl_Language[#All],MATCH("AttachEffect 3",Tbl_Language[English],0)+1,FALSE) -> 效果3 | B5: 7000802-縮短技藝的冷卻時間＋３ | D5: {=IF(B5<>"",_xlfn.CHOOSECOLS(_xlfn.TEXTSPLIT(B5,"-"),1),EmptyID)} -> 7000802 | E5: {=IF(D5<>EmptyID,VLOOKUP(VALUE(_xlfn.CHOOSECOLS(_xlfn.TEXTSPLIT(B5,"-"),1)),Tbl_Effect[],MATCH("overrideEffectId",Tbl_Effect[#Headers],0),FALSE),9999999999999)} -> 1000
A6: =HLOOKUP($B$1,Tbl_Language[#All],MATCH("CurseEffect 1",Tbl_Language[English],0)+1,FALSE) -> 負面1 | D6: {=IF(B6<>"",_xlfn.CHOOSECOLS(_xlfn.TEXTSPLIT(B6,"-"),1),EmptyID)} -> 4294967295 | E6: {=IF(D6<>EmptyID,VLOOKUP(VALUE(_xlfn.CHOOSECOLS(_xlfn.TEXTSPLIT(B6,"-"),1)),Tbl_Effect[],MATCH("overrideEffectId",Tbl_Effect[#Headers],0),FALSE),9999999999999)} -> 9999999999999
A7: =HLOOKUP($B$1,Tbl_Language[#All],MATCH("CurseEffect 2",Tbl_Language[English],0)+1,FALSE) -> 負面2 | D7: {=IF(B7<>"",_xlfn.CHOOSECOLS(_xlfn.TEXTSPLIT(B7,"-"),1),EmptyID)} -> 4294967295 | E7: {=IF(D7<>EmptyID,VLOOKUP(VALUE(_xlfn.CHOOSECOLS(_xlfn.TEXTSPLIT(B7,"-"),1)),Tbl_Effect[],MATCH("overrideEffectId",Tbl_Effect[#Headers],0),FALSE),9999999999999)} -> 9999999999999
A8: =HLOOKUP($B$1,Tbl_Language[#All],MATCH("CurseEffect 3",Tbl_Language[English],0)+1,FALSE) -> 負面3 | D8: {=IF(B8<>"",_xlfn.CHOOSECOLS(_xlfn.TEXTSPLIT(B8,"-"),1),EmptyID)} -> 4294967295 | E8: {=IF(D8<>EmptyID,VLOOKUP(VALUE(_xlfn.CHOOSECOLS(_xlfn.TEXTSPLIT(B8,"-"),1)),Tbl_Effect[],MATCH("overrideEffectId",Tbl_Effect[#Headers],0),FALSE),9999999999999)} -> 9999999999999
A11: =HLOOKUP($B$1,Tbl_Language[#All],MATCH("Final Result",Tbl_Language[English],0)+1,FALSE) -> 最終遺物結果 | B11: ID | C11: =HLOOKUP($B$1,Tbl_Language[#All],MATCH("Name And Description",Tbl_Language[English],0)+1,FALSE) -> 名稱/敘述
A12: =HLOOKUP($B$1,Tbl_Language[#All],MATCH("Relic",Tbl_Language[English],0)+1,FALSE) -> 遺物 | B12: {=IF(B2<>"",_xlfn.CHOOSECOLS(_xlfn.TEXTSPLIT(B2,"-"),1),"")} -> 229 | C12: =IF(B12<>"",VLOOKUP(B12+0,ItemText[],IFERROR(MATCH($B$1,ItemText[#Headers],0),2),FALSE),"") -> 遼闊的幽靜情景
A13: =HLOOKUP($B$1,Tbl_Language[#All],MATCH("AttachEffect 1",Tbl_Language[English],0)+1,FALSE) -> 效果1 | B13: {=_xlfn.SORTBY(D3:D5,E3:E5,1,D3:D5,1)} -> 7342400 | C13: =IF(B13<>EmptyID,VLOOKUP(VLOOKUP(B13+0,Tbl_Effect[],3,FALSE),EffectName[],IFERROR(MATCH($B$1,EffectName[#Headers],0),2),FALSE),"") -> 以弓攻擊時，恢復ＨＰ
A14: =HLOOKUP($B$1,Tbl_Language[#All],MATCH("AttachEffect 2",Tbl_Language[English],0)+1,FALSE) -> 效果2 | B14: 7000202 | C14: =IF(B14<>EmptyID,VLOOKUP(VLOOKUP(B14+0,Tbl_Effect[],3,FALSE),EffectName[],IFERROR(MATCH($B$1,EffectName[#Headers],0),2),FALSE),"") -> 耐力＋３
A15: =HLOOKUP($B$1,Tbl_Language[#All],MATCH("AttachEffect 3",Tbl_Language[English],0)+1,FALSE) -> 效果3 | B15: 7000802 | C15: =IF(B15<>EmptyID,VLOOKUP(VLOOKUP(B15+0,Tbl_Effect[],3,FALSE),EffectName[],IFERROR(MATCH($B$1,EffectName[#Headers],0),2),FALSE),"") -> 縮短技藝的冷卻時間＋３
A16: =HLOOKUP($B$1,Tbl_Language[#All],MATCH("CurseEffect 1",Tbl_Language[English],0)+1,FALSE) -> 負面1 | B16: {=_xlfn.SORTBY(D6:D8,E3:E5,1,D3:D5,1)} -> 4294967295 | C16: =IF(B16<>EmptyID,VLOOKUP(VLOOKUP(B16+0,Tbl_Effect[],3,FALSE),EffectName[],IFERROR(MATCH($B$1,EffectName[#Headers],0),2),FALSE),"")
A17: =HLOOKUP($B$1,Tbl_Language[#All],MATCH("CurseEffect 2",Tbl_Language[English],0)+1,FALSE) -> 負面2 | B17: 4294967295 | C17: =IF(B17<>EmptyID,VLOOKUP(VLOOKUP(B17+0,Tbl_Effect[],3,FALSE),EffectName[],IFERROR(MATCH($B$1,EffectName[#Headers],0),2),FALSE),"")
A18: =HLOOKUP($B$1,Tbl_Language[#All],MATCH("CurseEffect 3",Tbl_Language[English],0)+1,FALSE) -> 負面3 | B18: 4294967295 | C18: =IF(B18<>EmptyID,VLOOKUP(VLOOKUP(B18+0,Tbl_Effect[],3,FALSE),EffectName[],IFERROR(MATCH($B$1,EffectName[#Headers],0),2),FALSE),"")

Sheet UI Language
A1: English | B1: 繁體中文 | C1: 簡體中文
A2: Relic | B2: 遺物 | C2: 遗物
A3: AttachEffect 1 | B3: 效果1 | C3: 效果1
A4: AttachEffect 2 | B4: 效果2 | C4: 效果2
A5: AttachEffect 3 | B5: 效果3 | C5: 效果3
A6: CurseEffect 1 | B6: 負面1 | C6: 负面1
A7: CurseEffect 2 | B7: 負面2 | C7: 负面2
A8: CurseEffect 3 | B8: 負面3 | C8: 负面3
A9: Language | B9: 語言 | C9: 语言
A10: Final Result | B10: 最終遺物結果 | C10: 最终遗物结果
A11: Name And Description | B11: 名稱/敘述 | C11: 名称/叙述

Sheet Relic Cacul Temp
A1: Relic ID | B1: =VLOOKUP(UI!B2,$H2:$K2000,2,FALSE) -> 229 | H1: Relic | I1: Relic ID | J1: Relic Color | K1: Relic Name | L1: 效果池1 | M1: 效果池1 ID | N1: 效果池1 敘述 | O1: 效果池2 | P1: 效果池2 ID | Q1: 效果池2 敘述 | R1: 效果池3 | S1: 效果池3 ID | T1: 效果池3 敘述 | U1: 負面池1 | V1: 負面池1 ID | W1: 負面池1 敘述 | X1: 負面池2 | Y1: 負面池2 ID | Z1: 負面池2 敘述 | AA1: 負面池3 | AB1: 負面池3 ID | AC1: 負面池3 敘述 | AE1: AttachEffect 1 Temp | AF1: AttachEffect 2 Temp | AG1: AttachEffect 3 Temp | AH1: Curse1 Temp | AI1: Curse2 Temp | AJ1: Curse3 Temp
B2: 正面效果1 | C2: 正面效果2 | D2: 正面效果3 | E2: 負面效果1 | F2: 負面效果2 | G2: 負面效果3 | H2: =IF(VALUE(I2)<>0,I2&"-"&K2&" ("&J2&")","") -> 1-%null% (紅) | I2: {=_xlfn.EXPAND(Tbl_Equip[ID],2000,,0)} -> 1 | J2: =_xlfn.IFNA(IF(I2<>0,VLOOKUP(VLOOKUP(I2,Tbl_Equip[],2,FALSE),Tbl_Color[],IFERROR(MATCH(UI!$B$1,Tbl_Color[#Headers],0),2),FALSE),""),"Unset") -> 紅 | K2: =_xlfn.IFNA(IF(I2<>0,VLOOKUP(I2,ItemText[],IFERROR(MATCH(UI!$B$1,ItemText[#Headers],0),2),FALSE),""),"Unset") -> %null% | L2: =IF(VALUE(M2)=0,"",M2&"-"&N2) -> 7000000-生命力＋１ | M2: {=_xlfn.EXPAND(IF(B3=-1,0,_xlfn.ANCHORARRAY(AE2)),2000,,0)} -> 7000000 | N2: =IF(VALUE(M2)=0,"",VLOOKUP(VLOOKUP(M2,Tbl_Effect[],3,FALSE),EffectName[],IFERROR(MATCH(UI!$B$1,EffectName[#Headers],0),2),FALSE)) -> 生命力＋１ | O2: =IF(VALUE(P2)=0,"",P2&"-"&Q2) -> 7000000-生命力＋１ | P2: {=_xlfn.EXPAND(IF(C3=-1,0,_xlfn.ANCHORARRAY(AF2)),2000,,0)} -> 7000000 | Q2: =IF(VALUE(P2)=0,"",VLOOKUP(VLOOKUP(P2,Tbl_Effect[],3,FALSE),EffectName[],IFERROR(MATCH(UI!$B$1,EffectName[#Headers],0),2),FALSE)) -> 生命力＋１ | R2: =IF(VALUE(S2)=0,"",S2&"-"&T2) -> 7000000-生命力＋１ | S2: {=_xlfn.EXPAND(IF(D3=-1,0,_xlfn.ANCHORARRAY(AG2)),2000,,0)} -> 7000000 | T2: =IF(VALUE(S2)=0,"",VLOOKUP(VLOOKUP(S2,Tbl_Effect[],3,FALSE),EffectName[],IFERROR(MATCH(UI!$B$1,EffectName[#Headers],0),2),FALSE)) -> 生命力＋１ | U2: =IF(VALUE(V2)=0,"",V2&"-"&W2) | V2: {=_xlfn.EXPAND(IF(E3=-1,0,_xlfn.ANCHORARRAY(AH2)),2000,,0)} -> 0 | W2: =IF(V2<>0,VLOOKUP(VLOOKUP(V2,Tbl_Effect[],3,FALSE),EffectName[],IFERROR(MATCH(UI!$B$1,EffectName[#Headers],0),2),FALSE),"") | X2: =IF(VALUE(Y2)=0,"",Y2&"-"&Z2) | Y2: {=_xlfn.EXPAND(IF(F3=-1,0,_xlfn.ANCHORARRAY(AI2)),2000,,0)} -> 0 | Z2: =IF(Y2<>0,VLOOKUP(VLOOKUP(Y2,Tbl_Effect[],3,FALSE),EffectName[],IFERROR(MATCH(UI!$B$1,EffectName[#Headers],0),2),FALSE),"") | AA2: =IF(VALUE(AB2)=0,"",AB2&"-"&AC2) | AB2: {=_xlfn.EXPAND(IF(G3=-1,0,_xlfn.ANCHORARRAY(AJ2)),2000,,0)} -> 0 | AC2: =IF(AB2<>0,VLOOKUP(VLOOKUP(AB2,Tbl_Effect[],3,FALSE),EffectName[],IFERROR(MATCH(UI!$B$1,EffectName[#Headers],0),2),FALSE),"") | AE2: {=_xlfn._xlws.FILTER(Tbl_Pool[attachEffectId], Tbl_Pool[ID] = B3)} -> 7000000 | AF2: {=_xlfn.LET( _xlpm.CurrentPool, C3, _xlpm.Selected1, B4, _xlpm.Conflict1, IF(_xlpm.Selected1="", "###", _xlfn.XLOOKUP(_xlpm.Selected1, Tbl_Effect[欄1], Tbl_Effect[compatibilityId], "###")), _xlpm.PoolEffects, _xlfn._xlws.FILTER(Tbl_Pool[attachEffectId], Tbl_Pool[ID] = _xlpm.CurrentPool, "無符合效果"), IF(ISERROR(_xlpm.PoolEffects), "請先完成前置選擇", _xlfn._xlws.FILTER(_xlpm.PoolEffects, (_xlpm.PoolEffects <> _xlpm.Selected1) * ( (_xlpm.Conflict1 = -1) + (_xlfn.XLOOKUP(_xlpm.PoolEffects, Tbl_Effect[欄1], Tbl_Effect[compatibilityId], "") <> _xlpm.Conflict1) ) ) ) )} -> 7000000 | AG2: {=_xlfn.LET( _xlpm.CurrentPool, D3, _xlpm.Selected1, B4, _xlpm.Selected2, C4, _xlpm.Conflict1, IF(_xlpm.Selected1="", "###", _xlfn.XLOOKUP(_xlpm.Selected1, Tbl_Effect[欄1], Tbl_Effect[compatibilityId], "###")), _xlpm.Conflict2, IF(_xlpm.Selected2="", "###", _xlfn.XLOOKUP(_xlpm.Selected2, Tbl_Effect[欄1], Tbl_Effect[compatibilityId], "###")), _xlpm.PoolEffects, _xlfn._xlws.FILTER(Tbl_Pool[attachEffectId], Tbl_Pool[ID] = _xlpm.CurrentPool, "無符合效果"), IF(ISERROR(_xlpm.PoolEffects), "請先完成前置選擇", _xlfn._xlws.FILTER(_xlpm.PoolEffects, (_xlpm.PoolEffects <> _xlpm.Selected1) * (_xlpm.PoolEffects <> _xlpm.Selected2) * ((_xlpm.Conflict1 = -1) + (_xlfn.XLOOKUP(_xlpm.PoolEffects, Tbl_Effect[欄1], Tbl_Effect[compatibilityId], "") <> _xlpm.Conflict1)) * ((_xlpm.Conflict2 = -1) + (_xlfn.XLOOKUP(_xlpm.PoolEffects, Tbl_Effect[欄1], Tbl_Effect[compatibilityId], "") <> _xlpm.Conflict2)) ) ) )} -> 7000000 | AH2: {=IF(E3<>-1,_xlfn._xlws.FILTER(Tbl_Pool[attachEffectId], Tbl_Pool[ID] = E3),"無符合效果")} -> 無符合效果 | AI2: {=_xlfn.LET( _xlpm.CurrentPool, F3, _xlpm.CurseSelected1, E4, _xlpm.CurseConflict1, IF(_xlpm.CurseSelected1="", "###", _xlfn.XLOOKUP(_xlpm.CurseSelected1, Tbl_Effect[欄1], Tbl_Effect[compatibilityId], "###")), _xlpm.PoolEffects, _xlfn._xlws.FILTER(Tbl_Pool[attachEffectId], Tbl_Pool[ID] = _xlpm.CurrentPool, "無符合效果"), IF(ISERROR(_xlpm.PoolEffects), "請先完成前置選擇", _xlfn._xlws.FILTER(_xlpm.PoolEffects, (_xlpm.PoolEffects <> _xlpm.CurseSelected1) * ((_xlpm.CurseConflict1 = -1) + (_xlfn.XLOOKUP(_xlpm.PoolEffects, Tbl_Effect[欄1], Tbl_Effect[compatibilityId], "") <> _xlpm.CurseConflict1)) ) ) )} -> 無符合效果 | AJ2: {=_xlfn.LET( _xlpm.CurrentPool, G3, _xlpm.CurseSelected1, E4, _xlpm.CurseSelected2, F4, _xlpm.CurseConflict1, IF(_xlpm.CurseSelected1="", "###", _xlfn.XLOOKUP(_xlpm.CurseSelected1, Tbl_Effect[欄1], Tbl_Effect[compatibilityId], "###")), _xlpm.CurseConflict2, IF(_xlpm.CurseSelected2="", "###", _xlfn.XLOOKUP(_xlpm.CurseSelected2, Tbl_Effect[欄1], Tbl_Effect[compatibilityId], "###")), _xlpm.PoolEffects, _xlfn._xlws.FILTER(Tbl_Pool[attachEffectId], Tbl_Pool[ID] = _xlpm.CurrentPool, "無符合效果"), IF(ISERROR(_xlpm.PoolEffects), "請先完成前置選擇", _xlfn._xlws.FILTER(_xlpm.PoolEffects, (_xlpm.PoolEffects <> _xlpm.CurseSelected1) * (_xlpm.PoolEffects <> _xlpm.CurseSelected2) * (_xlfn.XLOOKUP(_xlpm.PoolEffects, Tbl_Effect[欄1], Tbl_Effect[compatibilityId], "") <> _xlpm.CurseConflict1) * (_xlfn.XLOOKUP(_xlpm.PoolEffects, Tbl_Effect[欄1], Tbl_Effect[compatibilityId], "") <> _xlpm.CurseConflict2) ) ) )} -> 無符合效果
A3: 效果池 | B3: =_xlfn.XLOOKUP($B$1, Tbl_Equip[ID], Tbl_Equip[attachEffectTableId_1]) -> 310 | C3: =_xlfn.XLOOKUP($B$1, Tbl_Equip[ID], Tbl_Equip[attachEffectTableId_2]) -> 210 | D3: =_xlfn.XLOOKUP($B$1, Tbl_Equip[ID], Tbl_Equip[attachEffectTableId_3]) -> 110 | E3: =_xlfn.XLOOKUP($B$1, Tbl_Equip[ID], Tbl_Equip[attachEffectTableId_curse1]) -> -1 | F3: =_xlfn.XLOOKUP($B$1, Tbl_Equip[ID], Tbl_Equip[attachEffectTableId_curse2]) -> -1 | G3: =_xlfn.XLOOKUP($B$1, Tbl_Equip[ID], Tbl_Equip[attachEffectTableId_curse3]) -> -1 | H3: =IF(VALUE(I3)<>0,I3&"-"&K3&" ("&J3&")","") -> 2-%null% (紅) | I3: 2 | J3: =_xlfn.IFNA(IF(I3<>0,VLOOKUP(VLOOKUP(I3,Tbl_Equip[],2,FALSE),Tbl_Color[],IFERROR(MATCH(UI!$B$1,Tbl_Color[#Headers],0),2),FALSE),""),"Unset") -> 紅 | K3: =_xlfn.IFNA(IF(I3<>0,VLOOKUP(I3,ItemText[],IFERROR(MATCH(UI!$B$1,ItemText[#Headers],0),2),FALSE),""),"Unset") -> %null% | L3: =IF(VALUE(M3)=0,"",M3&"-"&N3) -> 7000001-生命力＋２ | M3: 7000001 | N3: =IF(VALUE(M3)=0,"",VLOOKUP(VLOOKUP(M3,Tbl_Effect[],3,FALSE),EffectName[],IFERROR(MATCH(UI!$B$1,EffectName[#Headers],0),2),FALSE)) -> 生命力＋２ | O3: =IF(VALUE(P3)=0,"",P3&"-"&Q3) -> 7000001-生命力＋２ | P3: 7000001 | Q3: =IF(VALUE(P3)=0,"",VLOOKUP(VLOOKUP(P3,Tbl_Effect[],3,FALSE),EffectName[],IFERROR(MATCH(UI!$B$1,EffectName[#Headers],0),2),FALSE)) -> 生命力＋２ | R3: =IF(VALUE(S3)=0,"",S3&"-"&T3) -> 7000001-生命力＋２ | S3: 7000001 | T3: =IF(VALUE(S3)=0,"",VLOOKUP(VLOOKUP(S3,Tbl_Effect[],3,FALSE),EffectName[],IFERROR(MATCH(UI!$B$1,EffectName[#Headers],0),2),FALSE)) -> 生命力＋２ | U3: =IF(VALUE(V3)=0,"",V3&"-"&W3) | V3: 0 | W3: =IF(V3<>0,VLOOKUP(VLOOKUP(V3,Tbl_Effect[],3,FALSE),EffectName[],IFERROR(MATCH(UI!$B$1,EffectName[#Headers],0),2),FALSE),"") | X3: =IF(VALUE(Y3)=0,"",Y3&"-"&Z3) | Y3: 0 | Z3: =IF(Y3<>0,VLOOKUP(VLOOKUP(Y3,Tbl_Effect[],3,FALSE),EffectName[],IFERROR(MATCH(UI!$B$1,EffectName[#Headers],0),2),FALSE),"") | AA3: =IF(VALUE(AB3)=0,"",AB3&"-"&AC3) | AB3: 0 | AC3: =IF(AB3<>0,VLOOKUP(VLOOKUP(AB3,Tbl_Effect[],3,FALSE),EffectName[],IFERROR(MATCH(UI!$B$1,EffectName[#Headers],0),2),FALSE),"") | AE3: 7000001 | AF3: 7000001 | AG3: 7000001
A4: 效果 | B4: =IF(B3<>-1,VLOOKUP(UI!B3,L2:N2000,2,FALSE),"") -> 7000202 | C4: =IF(C3<>-1,VLOOKUP(UI!B4,O2:Q2000,2,FALSE),"") -> 7342400 | D4: =IF(D3<>-1,VLOOKUP(UI!B5,R2:T2000,2,FALSE),"") -> 7000802 | E4: =IF(E3<>-1,VLOOKUP(UI!B6,U2:W2000,2,FALSE),"") | F4: =IF(F3<>-1,VLOOKUP(UI!B7,X2:Z2000,2,FALSE),"") | G4: =IF(G3<>-1,VLOOKUP(UI!B8,AA2:AC2000,2,FALSE),"") | H4: =IF(VALUE(I4)<>0,I4&"-"&K4&" ("&J4&")","") -> 3-%null% (紅) | I4: 3 | J4: =_xlfn.IFNA(IF(I4<>0,VLOOKUP(VLOOKUP(I4,Tbl_Equip[],2,FALSE),Tbl_Color[],IFERROR(MATCH(UI!$B$1,Tbl_Color[#Headers],0),2),FALSE),""),"Unset") -> 紅 | K4: =_xlfn.IFNA(IF(I4<>0,VLOOKUP(I4,ItemText[],IFERROR(MATCH(UI!$B$1,ItemText[#Headers],0),2),FALSE),""),"Unset") -> %null% | L4: =IF(VALUE(M4)=0,"",M4&"-"&N4) -> 7000002-生命力＋３ | M4: 7000002 | N4: =IF(VALUE(M4)=0,"",VLOOKUP(VLOOKUP(M4,Tbl_Effect[],3,FALSE),EffectName[],IFERROR(MATCH(UI!$B$1,EffectName[#Headers],0),2),FALSE)) -> 生命力＋３ | O4: =IF(VALUE(P4)=0,"",P4&"-"&Q4) -> 7000002-生命力＋３ | P4: 7000002 | Q4: =IF(VALUE(P4)=0,"",VLOOKUP(VLOOKUP(P4,Tbl_Effect[],3,FALSE),EffectName[],IFERROR(MATCH(UI!$B$1,EffectName[#Headers],0),2),FALSE)) -> 生命力＋３ | R4: =IF(VALUE(S4)=0,"",S4&"-"&T4) -> 7000002-生命力＋３ | S4: 7000002 | T4: =IF(VALUE(S4)=0,"",VLOOKUP(VLOOKUP(S4,Tbl_Effect[],3,FALSE),EffectName[],IFERROR(MATCH(UI!$B$1,EffectName[#Headers],0),2),FALSE)) -> 生命力＋３ | U4: =IF(VALUE(V4)=0,"",V4&"-"&W4) | V4: 0 | W4: =IF(V4<>0,VLOOKUP(VLOOKUP(V4,Tbl_Effect[],3,FALSE),EffectName[],IFERROR(MATCH(UI!$B$1,EffectName[#Headers],0),2),FALSE),"") | X4: =IF(VALUE(Y4)=0,"",Y4&"-"&Z4) | Y4: 0 | Z4: =IF(Y4<>0,VLOOKUP(VLOOKUP(Y4,Tbl_Effect[],3,FALSE),EffectName[],IFERROR(MATCH(UI!$B$1,EffectName[#Headers],0),2),FALSE),"") | AA4: =IF(VALUE(AB4)=0,"",AB4&"-"&AC4) | AB4: 0 | AC4: =IF(AB4<>0,VLOOKUP(VLOOKUP(AB4,Tbl_Effect[],3,FALSE),EffectName[],IFERROR(MATCH(UI!$B$1,EffectName[#Headers],0),2),FALSE),"") | AE4: 7000002 | AF4: 7000002 | AG4: 7000002
H5: =IF(VALUE(I5)<>0,I5&"-"&K5&" ("&J5&")","") -> 4-%null% (紅) | I5: 4 | J5: =_xlfn.IFNA(IF(I5<>0,VLOOKUP(VLOOKUP(I5,Tbl_Equip[],2,FALSE),Tbl_Color[],IFERROR(MATCH(UI!$B$1,Tbl_Color[#Headers],0),2),FALSE),""),"Unset") -> 紅 | K5: =_xlfn.IFNA(IF(I5<>0,VLOOKUP(I5,ItemText[],IFERROR(MATCH(UI!$B$1,ItemText[#Headers],0),2),FALSE),""),"Unset") -> %null% | L5: =IF(VALUE(M5)=0,"",M5&"-"&N5) -> 7000100-集中力＋１ | M5: 7000100 | N5: =IF(VALUE(M5)=0,"",VLOOKUP(VLOOKUP(M5,Tbl_Effect[],3,FALSE),EffectName[],IFERROR(MATCH(UI!$B$1,EffectName[#Headers],0),2),FALSE)) -> 集中力＋１ | O5: =IF(VALUE(P5)=0,"",P5&"-"&Q5) -> 7000100-集中力＋１ | P5: 7000100 | Q5: =IF(VALUE(P5)=0,"",VLOOKUP(VLOOKUP(P5,Tbl_Effect[],3,FALSE),EffectName[],IFERROR(MATCH(UI!$B$1,EffectName[#Headers],0),2),FALSE)) -> 集中力＋１ | R5: =IF(VALUE(S5)=0,"",S5&"-"&T5) -> 7000100-集中力＋１ | S5: 7000100 | T5: =IF(VALUE(S5)=0,"",VLOOKUP(VLOOKUP(S5,Tbl_Effect[],3,FALSE),EffectName[],IFERROR(MATCH(UI!$B$1,EffectName[#Headers],0),2),FALSE)) -> 集中力＋１ | U5: =IF(VALUE(V5)=0,"",V5&"-"&W5) | V5: 0 | W5: =IF(V5<>0,VLOOKUP(VLOOKUP(V5,Tbl_Effect[],3,FALSE),EffectName[],IFERROR(MATCH(UI!$B$1,EffectName[#Headers],0),2),FALSE),"") | X5: =IF(VALUE(Y5)=0,"",Y5&"-"&Z5) | Y5: 0 | Z5: =IF(Y5<>0,VLOOKUP(VLOOKUP(Y5,Tbl_Effect[],3,FALSE),EffectName[],IFERROR(MATCH(UI!$B$1,EffectName[#Headers],0),2),FALSE),"") | AA5: =IF(VALUE(AB5)=0,"",AB5&"-"&AC5) | AB5: 0 | AC5: =IF(AB5<>0,VLOOKUP(VLOOKUP(AB5,Tbl_Effect[],3,FALSE),EffectName[],IFERROR(MATCH(UI!$B$1,EffectName[#Headers],0),2),FALSE),"") | AE5: 7000100 | AF5: 7000100 | AG5: 7000100
H6: =IF(VALUE(I6)<>0,I6&"-"&K6&" ("&J6&")","") -> 5-%null% (紅) | I6: 5 | J6: =_xlfn.IFNA(IF(I6<>0,VLOOKUP(VLOOKUP(I6,Tbl_Equip[],2,FALSE),Tbl_Color[],IFERROR(MATCH(UI!$B$1,Tbl_Color[#Headers],0),2),FALSE),""),"Unset") -> 紅 | K6: =_xlfn.IFNA(IF(I6<>0,VLOOKUP(I6,ItemText[],IFERROR(MATCH(UI!$B$1,ItemText[#Headers],0),2),FALSE),""),"Unset") -> %null% | L6: =IF(VALUE(M6)=0,"",M6&"-"&N6) -> 7000101-集中力＋２ | M6: 7000101 | N6: =IF(VALUE(M6)=0,"",VLOOKUP(VLOOKUP(M6,Tbl_Effect[],3,FALSE),EffectName[],IFERROR(MATCH(UI!$B$1,EffectName[#Headers],0),2),FALSE)) -> 集中力＋２ | O6: =IF(VALUE(P6)=0,"",P6&"-"&Q6) -> 7000101-集中力＋２ | P6: 7000101 | Q6: =IF(VALUE(P6)=0,"",VLOOKUP(VLOOKUP(P6,Tbl_Effect[],3,FALSE),EffectName[],IFERROR(MATCH(UI!$B$1,EffectName[#Headers],0),2),FALSE)) -> 集中力＋２ | R6: =IF(VALUE(S6)=0,"",S6&"-"&T6) -> 7000101-集中力＋２ | S6: 7000101 | T6: =IF(VALUE(S6)=0,"",VLOOKUP(VLOOKUP(S6,Tbl_Effect[],3,FALSE),EffectName[],IFERROR(MATCH(UI!$B$1,EffectName[#Headers],0),2),FALSE)) -> 集中力＋２ | U6: =IF(VALUE(V6)=0,"",V6&"-"&W6) | V6: 0 | W6: =IF(V6<>0,VLOOKUP(VLOOKUP(V6,Tbl_Effect[],3,FALSE),EffectName[],IFERROR(MATCH(UI!$B$1,EffectName[#Headers],0),2),FALSE),"") | X6: =IF(VALUE(Y6)=0,"",Y6&"-"&Z6) | Y6: 0 | Z6: =IF(Y6<>0,VLOOKUP(VLOOKUP(Y6,Tbl_Effect[],3,FALSE),EffectName[],IFERROR(MATCH(UI!$B$1,EffectName[#Headers],0),2),FALSE),"") | AA6: =IF(VALUE(AB6)=0,"",AB6&"-"&AC6) | AB6: 0 | AC6: =IF(AB6<>0,VLOOKUP(VLOOKUP(AB6,Tbl_Effect[],3,FALSE),EffectName[],IFERROR(MATCH(UI!$B$1,EffectName[#Headers],0),2),FALSE),"") | AE6: 7000101 | AF6: 7000101 | AG6: 7000101
H7: =IF(VALUE(I7)<>0,I7&"-"&K7&" ("&J7&")","") -> 6-%null% (紅) | I7: 6 | J7: =_xlfn.IFNA(IF(I7<>0,VLOOKUP(VLOOKUP(I7,Tbl_Equip[],2,FALSE),Tbl_Color[],IFERROR(MATCH(UI!$B$1,Tbl_Color[#Headers],0),2),FALSE),""),"Unset") -> 紅 | K7: =_xlfn.IFNA(IF(I7<>0,VLOOKUP(I7,ItemText[],IFERROR(MATCH(UI!$B$1,ItemText[#Headers],0),2),FALSE),""),"Unset") -> %null% | L7: =IF(VALUE(M7)=0,"",M7&"-"&N7) -> 7000102-集中力＋３ | M7: 7000102 | N7: =IF(VALUE(M7)=0,"",VLOOKUP(VLOOKUP(M7,Tbl_Effect[],3,FALSE),EffectName[],IFERROR(MATCH(UI!$B$1,EffectName[#Headers],0),2),FALSE)) -> 集中力＋３ | O7: =IF(VALUE(P7)=0,"",P7&"-"&Q7) -> 7000102-集中力＋３ | P7: 7000102 | Q7: =IF(VALUE(P7)=0,"",VLOOKUP(VLOOKUP(P7,Tbl_Effect[],3,FALSE),EffectName[],IFERROR(MATCH(UI!$B$1,EffectName[#Headers],0),2),FALSE)) -> 集中力＋３ | R7: =IF(VALUE(S7)=0,"",S7&"-"&T7) -> 7000102-集中力＋３ | S7: 7000102 | T7: =IF(VALUE(S7)=0,"",VLOOKUP(VLOOKUP(S7,Tbl_Effect[],3,FALSE),EffectName[],IFERROR(MATCH(UI!$B$1,EffectName[#Headers],0),2),FALSE)) -> 集中力＋３ | U7: =IF(VALUE(V7)=0,"",V7&"-"&W7) | V7: 0 | W7: =IF(V7<>0,VLOOKUP(VLOOKUP(V7,Tbl_Effect[],3,FALSE),EffectName[],IFERROR(MATCH(UI!$B$1,EffectName[#Headers],0),2),FALSE),"") | X7: =IF(VALUE(Y7)=0,"",Y7&"-"&Z7) | Y7: 0 | Z7: =IF(Y7<>0,VLOOKUP(VLOOKUP(Y7,Tbl_Effect[],3,FALSE),EffectName[],IFERROR(MATCH(UI!$B$1,EffectName[#Headers],0),2),FALSE),"") | AA7: =IF(VALUE(AB7)=0,"",AB7&"-"&AC7) | AB7: 0 | AC7: =IF(AB7<>0,VLOOKUP(VLOOKUP(AB7,Tbl_Effect[],3,FALSE),EffectName[],IFERROR(MATCH(UI!$B$1,EffectName[#Headers],0),2),FALSE),"") | AE7: 7000102 | AF7: 7000102 | AG7: 7000102
H8: =IF(VALUE(I8)<>0,I8&"-"&K8&" ("&J8&")","") -> 10-暗痕 (紅) | I8: 10 | J8: =_xlfn.IFNA(IF(I8<>0,VLOOKUP(VLOOKUP(I8,Tbl_Equip[],2,FALSE),Tbl_Color[],IFERROR(MATCH(UI!$B$1,Tbl_Color[#Headers],0),2),FALSE),""),"Unset") -> 紅 | K8: =_xlfn.IFNA(IF(I8<>0,VLOOKUP(I8,ItemText[],IFERROR(MATCH(UI!$B$1,ItemText[#Headers],0),2),FALSE),""),"Unset") -> 暗痕 | L8: =IF(VALUE(M8)=0,"",M8&"-"&N8) -> 7000200-耐力＋１ | M8: 7000200 | N8: =IF(VALUE(M8)=0,"",VLOOKUP(VLOOKUP(M8,Tbl_Effect[],3,FALSE),EffectName[],IFERROR(MATCH(UI!$B$1,EffectName[#Headers],0),2),FALSE)) -> 耐力＋１ | O8: =IF(VALUE(P8)=0,"",P8&"-"&Q8) -> 7000300-力氣＋１ | P8: 7000300 | Q8: =IF(VALUE(P8)=0,"",VLOOKUP(VLOOKUP(P8,Tbl_Effect[],3,FALSE),EffectName[],IFERROR(MATCH(UI!$B$1,EffectName[#Headers],0),2),FALSE)) -> 力氣＋１ | R8: =IF(VALUE(S8)=0,"",S8&"-"&T8) -> 7000300-力氣＋１ | S8: 7000300 | T8: =IF(VALUE(S8)=0,"",VLOOKUP(VLOOKUP(S8,Tbl_Effect[],3,FALSE),EffectName[],IFERROR(MATCH(UI!$B$1,EffectName[#Headers],0),2),FALSE)) -> 力氣＋１ | U8: =IF(VALUE(V8)=0,"",V8&"-"&W8) | V8: 0 | W8: =IF(V8<>0,VLOOKUP(VLOOKUP(V8,Tbl_Effect[],3,FALSE),EffectName[],IFERROR(MATCH(UI!$B$1,EffectName[#Headers],0),2),FALSE),"") | X8: =IF(VALUE(Y8)=0,"",Y8&"-"&Z8) | Y8: 0 | Z8: =IF(Y8<>0,VLOOKUP(VLOOKUP(Y8,Tbl_Effect[],3,FALSE),EffectName[],IFERROR(MATCH(UI!$B$1,EffectName[#Headers],0),2),FALSE),"") | AA8: =IF(VALUE(AB8)=0,"",AB8&"-"&AC8) | AB8: 0 | AC8: =IF(AB8<>0,VLOOKUP(VLOOKUP(AB8,Tbl_Effect[],3,FALSE),EffectName[],IFERROR(MATCH(UI!$B$1,EffectName[#Headers],0),2),FALSE),"") | AE8: 7000200 | AF8: 7000300 | AG8: 7000300
H9: =IF(VALUE(I9)<>0,I9&"-"&K9&" ("&J9&")","") -> 11-為王之證 (紅) | I9: 11 | J9: =_xlfn.IFNA(IF(I9<>0,VLOOKUP(VLOOKUP(I9,Tbl_Equip[],2,FALSE),Tbl_Color[],IFERROR(MATCH(UI!$B$1,Tbl_Color[#Headers],0),2),FALSE),""),"Unset") -> 紅 | K9: =_xlfn.IFNA(IF(I9<>0,VLOOKUP(I9,ItemText[],IFERROR(MATCH(UI!$B$1,ItemText[#Headers],0),2),FALSE),""),"Unset") -> 為王之證 | L9: =IF(VALUE(M9)=0,"",M9&"-"&N9) -> 7000201-耐力＋２ | M9: 7000201 | N9: =IF(VALUE(M9)=0,"",VLOOKUP(VLOOKUP(M9,Tbl_Effect[],3,FALSE),EffectName[],IFERROR(MATCH(UI!$B$1,EffectName[#Headers],0),2),FALSE)) -> 耐力＋２ | O9: =IF(VALUE(P9)=0,"",P9&"-"&Q9) -> 7000301-力氣＋２ | P9: 7000301 | Q9: =IF(VALUE(P9)=0,"",VLOOKUP(VLOOKUP(P9,Tbl_Effect[],3,FALSE),EffectName[],IFERROR(MATCH(UI!$B$1,EffectName[#Headers],0),2),FALSE)) -> 力氣＋２ | R9: =IF(VALUE(S9)=0,"",S9&"-"&T9) -> 7000301-力氣＋２ | S9: 7000301 | T9: =IF(VALUE(S9)=0,"",VLOOKUP(VLOOKUP(S9,Tbl_Effect[],3,FALSE),EffectName[],IFERROR(MATCH(UI!$B$1,EffectName[#Headers],0),2),FALSE)) -> 力氣＋２ | U9: =IF(VALUE(V9)=0,"",V9&"-"&W9) | V9: 0 | W9: =IF(V9<>0,VLOOKUP(VLOOKUP(V9,Tbl_Effect[],3,FALSE),EffectName[],IFERROR(MATCH(UI!$B$1,EffectName[#Headers],0),2),FALSE),"") | X9: =IF(VALUE(Y9)=0,"",Y9&"-"&Z9) | Y9: 0 | Z9: =IF(Y9<>0,VLOOKUP(VLOOKUP(Y9,Tbl_Effect[],3,FALSE),EffectName[],IFERROR(MATCH(UI!$B$1,EffectName[#Headers],0),2),FALSE),"") | AA9: =IF(VALUE(AB9)=0,"",AB9&"-"&AC9) | AB9: 0 | AC9: =IF(AB9<>0,VLOOKUP(VLOOKUP(AB9,Tbl_Effect[],3,FALSE),EffectName[],IFERROR(MATCH(UI!$B$1,EffectName[#Headers],0),2),FALSE),"") | AE9: 7000201 | AF9: 7000301 | AG9: 7000301
H10: =IF(VALUE(I10)<>0,I10&"-"&K10&" ("&J10&")","") -> 20-情景原石 (紅) | I10: 20 | J10: =_xlfn.IFNA(IF(I10<>0,VLOOKUP(VLOOKUP(I10,Tbl_Equip[],2,FALSE),Tbl_Color[],IFERROR(MATCH(UI!$B$1,Tbl_Color[#Headers],0),2),FALSE),""),"Unset") -> 紅 | K10: =_xlfn.IFNA(IF(I10<>0,VLOOKUP(I10,ItemText[],IFERROR(MATCH(UI!$B$1,ItemText[#Headers],0),2),FALSE),""),"Unset") -> 情景原石 | L10: =IF(VALUE(M10)=0,"",M10&"-"&N10) -> 7000202-耐力＋３ | M10: 7000202 | N10: =IF(VALUE(M10)=0,"",VLOOKUP(VLOOKUP(M10,Tbl_Effect[],3,FALSE),EffectName[],IFERROR(MATCH(UI!$B$1,EffectName[#Headers],0),2),FALSE)) -> 耐力＋３ | O10: =IF(VALUE(P10)=0,"",P10&"-"&Q10) -> 7000302-力氣＋３ | P10: 7000302 | Q10: =IF(VALUE(P10)=0,"",VLOOKUP(VLOOKUP(P10,Tbl_Effect[],3,FALSE),EffectName[],IFERROR(MATCH(UI!$B$1,EffectName[#Headers],0),2),FALSE)) -> 力氣＋３ | R10: =IF(VALUE(S10)=0,"",S10&"-"&T10) -> 7000302-力氣＋３ | S10: 7000302 | T10: =IF(VALUE(S10)=0,"",VLOOKUP(VLOOKUP(S10,Tbl_Effect[],3,FALSE),EffectName[],IFERROR(MATCH(UI!$B$1,EffectName[#Headers],0),2),FALSE)) -> 力氣＋３ | U10: =IF(VALUE(V10)=0,"",V10&"-"&W10) | V10: 0 | W10: =IF(V10<>0,VLOOKUP(VLOOKUP(V10,Tbl_Effect[],3,FALSE),EffectName[],IFERROR(MATCH(UI!$B$1,EffectName[#Headers],0),2),FALSE),"") | X10: =IF(VALUE(Y10)=0,"",Y10&"-"&Z10) | Y10: 0 | Z10: =IF(Y10<>0,VLOOKUP(VLOOKUP(Y10,Tbl_Effect[],3,FALSE),EffectName[],IFERROR(MATCH(UI!$B$1,EffectName[#Headers],0),2),FALSE),"") | AA10: =IF(VALUE(AB10)=0,"",AB10&"-"&AC10) | AB10: 0 | AC10: =IF(AB10<>0,VLOOKUP(VLOOKUP(AB10,Tbl_Effect[],3,FALSE),EffectName[],IFERROR(MATCH(UI!$B$1,EffectName[#Headers],0),2),FALSE),"") | AE10: 7000202 | AF10: 7000302 | AG10: 7000302
H11: =IF(VALUE(I11)<>0,I11&"-"&K11&" ("&J11&")","") -> 100-細膩的火燃情景 (紅) | I11: 100 | J11: =_xlfn.IFNA(IF(I11<>0,VLOOKUP(VLOOKUP(I11,Tbl_Equip[],2,FALSE),Tbl_Color[],IFERROR(MATCH(UI!$B$1,Tbl_Color[#Headers],0),2),FALSE),""),"Unset") -> 紅 | K11: =_xlfn.IFNA(IF(I11<>0,VLOOKUP(I11,ItemText[],IFERROR(MATCH(UI!$B$1,ItemText[#Headers],0),2),FALSE),""),"Unset") -> 細膩的火燃情景 | L11: =IF(VALUE(M11)=0,"",M11&"-"&N11) -> 7000300-力氣＋１ | M11: 7000300 | N11: =IF(VALUE(M11)=0,"",VLOOKUP(VLOOKUP(M11,Tbl_Effect[],3,FALSE),EffectName[],IFERROR(MATCH(UI!$B$1,EffectName[#Headers],0),2),FALSE)) -> 力氣＋１ | O11: =IF(VALUE(P11)=0,"",P11&"-"&Q11) -> 7000400-靈巧＋１ | P11: 7000400 | Q11: =IF(VALUE(P11)=0,"",VLOOKUP(VLOOKUP(P11,Tbl_Effect[],3,FALSE),EffectName[],IFERROR(MATCH(UI!$B$1,EffectName[#Headers],0),2),FALSE)) -> 靈巧＋１ | R11: =IF(VALUE(S11)=0,"",S11&"-"&T11) -> 7000400-靈巧＋１ | S11: 7000400 | T11: =IF(VALUE(S11)=0,"",VLOOKUP(VLOOKUP(S11,Tbl_Effect[],3,FALSE),EffectName[],IFERROR(MATCH(UI!$B$1,EffectName[#Headers],0),2),FALSE)) -> 靈巧＋１ | U11: =IF(VALUE(V11)=0,"",V11&"-"&W11) | V11: 0 | W11: =IF(V11<>0,VLOOKUP(VLOOKUP(V11,Tbl_Effect[],3,FALSE),EffectName[],IFERROR(MATCH(UI!$B$1,EffectName[#Headers],0),2),FALSE),"") | X11: =IF(VALUE(Y11)=0,"",Y11&"-"&Z11) | Y11: 0 | Z11: =IF(Y11<>0,VLOOKUP(VLOOKUP(Y11,Tbl_Effect[],3,FALSE),EffectName[],IFERROR(MATCH(UI!$B$1,EffectName[#Headers],0),2),FALSE),"") | AA11: =IF(VALUE(AB11)=0,"",AB11&"-"&AC11) | AB11: 0 | AC11: =IF(AB11<>0,VLOOKUP(VLOOKUP(AB11,Tbl_Effect[],3,FALSE),EffectName[],IFERROR(MATCH(UI!$B$1,EffectName[#Headers],0),2),FALSE),"") | AE11: 7000300 | AF11: 7000400 | AG11: 7000400
H12: =IF(VALUE(I12)<>0,I12&"-"&K12&" ("&J12&")","") -> 101-端正的火燃情景 (紅) | I12: 101 | J12: =_xlfn.IFNA(IF(I12<>0,VLOOKUP(VLOOKUP(I12,Tbl_Equip[],2,FALSE),Tbl_Color[],IFERROR(MATCH(UI!$B$1,Tbl_Color[#Headers],0),2),FALSE),""),"Unset") -> 紅 | K12: =_xlfn.IFNA(IF(I12<>0,VLOOKUP(I12,ItemText[],IFERROR(MATCH(UI!$B$1,ItemText[#Headers],0),2),FALSE),""),"Unset") -> 端正的火燃情景 | L12: =IF(VALUE(M12)=0,"",M12&"-"&N12) -> 7000301-力氣＋２ | M12: 7000301 | N12: =IF(VALUE(M12)=0,"",VLOOKUP(VLOOKUP(M12,Tbl_Effect[],3,FALSE),EffectName[],IFERROR(MATCH(UI!$B$1,EffectName[#Headers],0),2),FALSE)) -> 力氣＋２ | O12: =IF(VALUE(P12)=0,"",P12&"-"&Q12) -> 7000401-靈巧＋２ | P12: 7000401 | Q12: =IF(VALUE(P12)=0,"",VLOOKUP(VLOOKUP(P12,Tbl_Effect[],3,FALSE),EffectName[],IFERROR(MATCH(UI!$B$1,EffectName[#Headers],0),2),FALSE)) -> 靈巧＋２ | R12: =IF(VALUE(S12)=0,"",S12&"-"&T12) -> 7000401-靈巧＋２ | S12: 7000401 | T12: =IF(VALUE(S12)=0,"",VLOOKUP(VLOOKUP(S12,Tbl_Effect[],3,FALSE),EffectName[],IFERROR(MATCH(UI!$B$1,EffectName[#Headers],0),2),FALSE)) -> 靈巧＋２ | U12: =IF(VALUE(V12)=0,"",V12&"-"&W12) | V12: 0 | W12: =IF(V12<>0,VLOOKUP(VLOOKUP(V12,Tbl_Effect[],3,FALSE),EffectName[],IFERROR(MATCH(UI!$B$1,EffectName[#Headers],0),2),FALSE),"") | X12: =IF(VALUE(Y12)=0,"",Y12&"-"&Z12) | Y12: 0 | Z12: =IF(Y12<>0,VLOOKUP(VLOOKUP(Y12,Tbl_Effect[],3,FALSE),EffectName[],IFERROR(MATCH(UI!$B$1,EffectName[#Headers],0),2),FALSE),"") | AA12: =IF(VALUE(AB12)=0,"",AB12&"-"&AC12) | AB12: 0 | AC12: =IF(AB12<>0,VLOOKUP(VLOOKUP(AB12,Tbl_Effect[],3,FALSE),EffectName[],IFERROR(MATCH(UI!$B$1,EffectName[#Headers],0),2),FALSE),"") | AE12: 7000301 | AF12: 7000401 | AG12: 7000401
H13: =IF(VALUE(I13)<>0,I13&"-"&K13&" ("&J13&")","") -> 102-遼闊的火燃情景 (紅) | I13: 102 | J13: =_xlfn.IFNA(IF(I13<>0,VLOOKUP(VLOOKUP(I13,Tbl_Equip[],2,FALSE),Tbl_Color[],IFERROR(MATCH(UI!$B$1,Tbl_Color[#Headers],0),2),FALSE),""),"Unset") -> 紅 | K13: =_xlfn.IFNA(IF(I13<>0,VLOOKUP(I13,ItemText[],IFERROR(MATCH(UI!$B$1,ItemText[#Headers],0),2),FALSE),""),"Unset") -> 遼闊的火燃情景 | L13: =IF(VALUE(M13)=0,"",M13&"-"&N13) -> 7000302-力氣＋３ | M13: 7000302 | N13: =IF(VALUE(M13)=0,"",VLOOKUP(VLOOKUP(M13,Tbl_Effect[],3,FALSE),EffectName[],IFERROR(MATCH(UI!$B$1,EffectName[#Headers],0),2),FALSE)) -> 力氣＋３ | O13: =IF(VALUE(P13)=0,"",P13&"-"&Q13) -> 7000402-靈巧＋３ | P13: 7000402 | Q13: =IF(VALUE(P13)=0,"",VLOOKUP(VLOOKUP(P13,Tbl_Effect[],3,FALSE),EffectName[],IFERROR(MATCH(UI!$B$1,EffectName[#Headers],0),2),FALSE)) -> 靈巧＋３ | R13: =IF(VALUE(S13)=0,"",S13&"-"&T13) -> 7000402-靈巧＋３ | S13: 7000402 | T13: =IF(VALUE(S13)=0,"",VLOOKUP(VLOOKUP(S13,Tbl_Effect[],3,FALSE),EffectName[],IFERROR(MATCH(UI!$B$1,EffectName[#Headers],0),2),FALSE)) -> 靈巧＋３ | U13: =IF(VALUE(V13)=0,"",V13&"-"&W13) | V13: 0 | W13: =IF(V13<>0,VLOOKUP(VLOOKUP(V13,Tbl_Effect[],3,FALSE),EffectName[],IFERROR(MATCH(UI!$B$1,EffectName[#Headers],0),2),FALSE),"") | X13: =IF(VALUE(Y13)=0,"",Y13&"-"&Z13) | Y13: 0 | Z13: =IF(Y13<>0,VLOOKUP(VLOOKUP(Y13,Tbl_Effect[],3,FALSE),EffectName[],IFERROR(MATCH(UI!$B$1,EffectName[#Headers],0),2),FALSE),"") | AA13: =IF(VALUE(AB13)=0,"",AB13&"-"&AC13) | AB13: 0 | AC13: =IF(AB13<>0,VLOOKUP(VLOOKUP(AB13,Tbl_Effect[],3,FALSE),EffectName[],IFERROR(MATCH(UI!$B$1,EffectName[#Headers],0),2),FALSE),"") | AE13: 7000302 | AF13: 7000402 | AG13: 7000402
H14: =IF(VALUE(I14)<>0,I14&"-"&K14&" ("&J14&")","") -> 103-細膩的火燃情景 (紅) | I14: 103 | J14: =_xlfn.IFNA(IF(I14<>0,VLOOKUP(VLOOKUP(I14,Tbl_Equip[],2,FALSE),Tbl_Color[],IFERROR(MATCH(UI!$B$1,Tbl_Color[#Headers],0),2),FALSE),""),"Unset") -> 紅 | K14: =_xlfn.IFNA(IF(I14<>0,VLOOKUP(I14,ItemText[],IFERROR(MATCH(UI!$B$1,ItemText[#Headers],0),2),FALSE),""),"Unset") -> 細膩的火燃情景 | L14: =IF(VALUE(M14)=0,"",M14&"-"&N14) -> 7000400-靈巧＋１ | M14: 7000400 | N14: =IF(VALUE(M14)=0,"",VLOOKUP(VLOOKUP(M14,Tbl_Effect[],3,FALSE),EffectName[],IFERROR(MATCH(UI!$B$1,EffectName[#Headers],0),2),FALSE)) -> 靈巧＋１ | O14: =IF(VALUE(P14)=0,"",P14&"-"&Q14) -> 7000500-智力＋１ | P14: 7000500 | Q14: =IF(VALUE(P14)=0,"",VLOOKUP(VLOOKUP(P14,Tbl_Effect[],3,FALSE),EffectName[],IFERROR(MATCH(UI!$B$1,EffectName[#Headers],0),2),FALSE)) -> 智力＋１ | R14: =IF(VALUE(S14)=0,"",S14&"-"&T14) -> 7000500-智力＋１ | S14: 7000500 | T14: =IF(VALUE(S14)=0,"",VLOOKUP(VLOOKUP(S14,Tbl_Effect[],3,FALSE),EffectName[],IFERROR(MATCH(UI!$B$1,EffectName[#Headers],0),2),FALSE)) -> 智力＋１ | U14: =IF(VALUE(V14)=0,"",V14&"-"&W14) | V14: 0 | W14: =IF(V14<>0,VLOOKUP(VLOOKUP(V14,Tbl_Effect[],3,FALSE),EffectName[],IFERROR(MATCH(UI!$B$1,EffectName[#Headers],0),2),FALSE),"") | X14: =IF(VALUE(Y14)=0,"",Y14&"-"&Z14) | Y14: 0 | Z14: =IF(Y14<>0,VLOOKUP(VLOOKUP(Y14,Tbl_Effect[],3,FALSE),EffectName[],IFERROR(MATCH(UI!$B$1,EffectName[#Headers],0),2),FALSE),"") | AA14: =IF(VALUE(AB14)=0,"",AB14&"-"&AC14) | AB14: 0 | AC14: =IF(AB14<>0,VLOOKUP(VLOOKUP(AB14,Tbl_Effect[],3,FALSE),EffectName[],IFERROR(MATCH(UI!$B$1,EffectName[#Headers],0),2),FALSE),"") | AE14: 7000400 | AF14: 7000500 | AG14: 7000500
H15: =IF(VALUE(I15)<>0,I15&"-"&K15&" ("&J15&")","") -> 104-端正的火燃情景 (紅) | I15: 104 | J15: =_xlfn.IFNA(IF(I15<>0,VLOOKUP(VLOOKUP(I15,Tbl_Equip[],2,FALSE),Tbl_Color[],IFERROR(MATCH(UI!$B$1,Tbl_Color[#Headers],0),2),FALSE),""),"Unset") -> 紅 | K15: =_xlfn.IFNA(IF(I15<>0,VLOOKUP(I15,ItemText[],IFERROR(MATCH(UI!$B$1,ItemText[#Headers],0),2),FALSE),""),"Unset") -> 端正的火燃情景 | L15: =IF(VALUE(M15)=0,"",M15&"-"&N15) -> 7000401-靈巧＋２ | M15: 7000401 | N15: =IF(VALUE(M15)=0,"",VLOOKUP(VLOOKUP(M15,Tbl_Effect[],3,FALSE),EffectName[],IFERROR(MATCH(UI!$B$1,EffectName[#Headers],0),2),FALSE)) -> 靈巧＋２ | O15: =IF(VALUE(P15)=0,"",P15&"-"&Q15) -> 7000501-智力＋２ | P15: 7000501 | Q15: =IF(VALUE(P15)=0,"",VLOOKUP(VLOOKUP(P15,Tbl_Effect[],3,FALSE),EffectName[],IFERROR(MATCH(UI!$B$1,EffectName[#Headers],0),2),FALSE)) -> 智力＋２ | R15: =IF(VALUE(S15)=0,"",S15&"-"&T15) -> 7000501-智力＋２ | S15: 7000501 | T15: =IF(VALUE(S15)=0,"",VLOOKUP(VLOOKUP(S15,Tbl_Effect[],3,FALSE),EffectName[],IFERROR(MATCH(UI!$B$1,EffectName[#Headers],0),2),FALSE)) -> 智力＋２ | U15: =IF(VALUE(V15)=0,"",V15&"-"&W15) | V15: 0 | W15: =IF(V15<>0,VLOOKUP(VLOOKUP(V15,Tbl_Effect[],3,FALSE),EffectName[],IFERROR(MATCH(UI!$B$1,EffectName[#Headers],0),2),FALSE),"") | X15: =IF(VALUE(Y15)=0,"",Y15&"-"&Z15) | Y15: 0 | Z15: =IF(Y15<>0,VLOOKUP(VLOOKUP(Y15,Tbl_Effect[],3,FALSE),EffectName[],IFERROR(MATCH(UI!$B$1,EffectName[#Headers],0),2),FALSE),"") | AA15: =IF(VALUE(AB15)=0,"",AB15&"-"&AC15) | AB15: 0 | AC15: =IF(AB15<>0,VLOOKUP(VLOOKUP(AB15,Tbl_Effect[],3,FALSE),EffectName[],IFERROR(MATCH(UI!$B$1,EffectName[#Headers],0),2),FALSE),"") | AE15: 7000401 | AF15: 7000501 | AG15: 7000501
H16: =IF(VALUE(I16)<>0,I16&"-"&K16&" ("&J16&")","") -> 105-遼闊的火燃情景 (紅) | I16: 105 | J16: =_xlfn.IFNA(IF(I16<>0,VLOOKUP(VLOOKUP(I16,Tbl_Equip[],2,FALSE),Tbl_Color[],IFERROR(MATCH(UI!$B$1,Tbl_Color[#Headers],0),2),FALSE),""),"Unset") -> 紅 | K16: =_xlfn.IFNA(IF(I16<>0,VLOOKUP(I16,ItemText[],IFERROR(MATCH(UI!$B$1,ItemText[#Headers],0),2),FALSE),""),"Unset") -> 遼闊的火燃情景 | L16: =IF(VALUE(M16)=0,"",M16&"-"&N16) -> 7000402-靈巧＋３ | M16: 7000402 | N16: =IF(VALUE(M16)=0,"",VLOOKUP(VLOOKUP(M16,Tbl_Effect[],3,FALSE),EffectName[],IFERROR(MATCH(UI!$B$1,EffectName[#Headers],0),2),FALSE)) -> 靈巧＋３ | O16: =IF(VALUE(P16)=0,"",P16&"-"&Q16) -> 7000502-智力＋３ | P16: 7000502 | Q16: =IF(VALUE(P16)=0,"",VLOOKUP(VLOOKUP(P16,Tbl_Effect[],3,FALSE),EffectName[],IFERROR(MATCH(UI!$B$1,EffectName[#Headers],0),2),FALSE)) -> 智力＋３ | R16: =IF(VALUE(S16)=0,"",S16&"-"&T16) -> 7000502-智力＋３ | S16: 7000502 | T16: =IF(VALUE(S16)=0,"",VLOOKUP(VLOOKUP(S16,Tbl_Effect[],3,FALSE),EffectName[],IFERROR(MATCH(UI!$B$1,EffectName[#Headers],0),2),FALSE)) -> 智力＋３ | U16: =IF(VALUE(V16)=0,"",V16&"-"&W16) | V16: 0 | W16: =IF(V16<>0,VLOOKUP(VLOOKUP(V16,Tbl_Effect[],3,FALSE),EffectName[],IFERROR(MATCH(UI!$B$1,EffectName[#Headers],0),2),FALSE),"") | X16: =IF(VALUE(Y16)=0,"",Y16&"-"&Z16) | Y16: 0 | Z16: =IF(Y16<>0,VLOOKUP(VLOOKUP(Y16,Tbl_Effect[],3,FALSE),EffectName[],IFERROR(MATCH(UI!$B$1,EffectName[#Headers],0),2),FALSE),"") | AA16: =IF(VALUE(AB16)=0,"",AB16&"-"&AC16) | AB16: 0 | AC16: =IF(AB16<>0,VLOOKUP(VLOOKUP(AB16,Tbl_Effect[],3,FALSE),EffectName[],IFERROR(MATCH(UI!$B$1,EffectName[#Headers],0),2),FALSE),"") | AE16: 7000402 | AF16: 7000502 | AG16: 7000502
... H335: =IF(VALUE(I335)<>0,I335&"-"&K335&" ("&J335&")","") -> 1001220-細膩的光耀情景 (黃) | I335: 1001220 | J335: =_xlfn.IFNA(IF(I335<>0,VLOOKUP(VLOOKUP(I335,Tbl_Equip[],2,FALSE),Tbl_Color[],IFERROR(MATCH(UI!$B$1,Tbl_Color[#Headers],0),2),FALSE),""),"Unset") -> 黃 | K335: =_xlfn.IFNA(IF(I335<>0,VLOOKUP(I335,ItemText[],IFERROR(MATCH(UI!$B$1,ItemText[#Headers],0),2),FALSE),""),"Unset") -> 細膩的光耀情景 | L335: =IF(VALUE(M335)=0,"",M335&"-"&N335) -> 6632500-透過潛在能力，能比較容易找到弩 | M335: 6632500 | N335: =IF(VALUE(M335)=0,"",VLOOKUP(VLOOKUP(M335,Tbl_Effect[],3,FALSE),EffectName[],IFERROR(MATCH(UI!$B$1,EffectName[#Headers],0),2),FALSE)) -> 透過潛在能力，能比較容易找到弩 | O335: =IF(VALUE(P335)=0,"",P335&"-"&Q335) -> 6632800-透過潛在能力，能比較容易找到中盾 | P335: 6632800 | Q335: =IF(VALUE(P335)=0,"",VLOOKUP(VLOOKUP(P335,Tbl_Effect[],3,FALSE),EffectName[],IFERROR(MATCH(UI!$B$1,EffectName[#Headers],0),2),FALSE)) -> 透過潛在能力，能比較容易找到中盾 | R335: =IF(VALUE(S335)=0,"",S335&"-"&T335) -> 6647100-【執行者】提升靈巧、感應，但降低生命力 | S335: 6647100 | T335: =IF(VALUE(S335)=0,"",VLOOKUP(VLOOKUP(S335,Tbl_Effect[],3,FALSE),EffectName[],IFERROR(MATCH(UI!$B$1,EffectName[#Headers],0),2),FALSE)) -> 【執行者】提升靈巧、感應，但降低生命力 | U335: =IF(VALUE(V335)=0,"",V335&"-"&W335) | V335: 0 | W335: =IF(V335<>0,VLOOKUP(VLOOKUP(V335,Tbl_Effect[],3,FALSE),EffectName[],IFERROR(MATCH(UI!$B$1,EffectName[#Headers],0),2),FALSE),"") | X335: =IF(VALUE(Y335)=0,"",Y335&"-"&Z335) | Y335: 0 | Z335: =IF(Y335<>0,VLOOKUP(VLOOKUP(Y335,Tbl_Effect[],3,FALSE),EffectName[],IFERROR(MATCH(UI!$B$1,EffectName[#Headers],0),2),FALSE),"") | AA335: =IF(VALUE(AB335)=0,"",AB335&"-"&AC335) | AB335: 0 | AC335: =IF(AB335<>0,VLOOKUP(VLOOKUP(AB335,Tbl_Effect[],3,FALSE),EffectName[],IFERROR(MATCH(UI!$B$1,EffectName[#Headers],0),2),FALSE),"") | AE335: 6632500 | AF335: 6632800 | AG335: 6647100
H336: =IF(VALUE(I336)<>0,I336&"-"&K336&" ("&J336&")","") -> 1001221-端正的光耀情景 (黃) | I336: 1001221 | J336: =_xlfn.IFNA(IF(I336<>0,VLOOKUP(VLOOKUP(I336,Tbl_Equip[],2,FALSE),Tbl_Color[],IFERROR(MATCH(UI!$B$1,Tbl_Color[#Headers],0),2),FALSE),""),"Unset") -> 黃 | K336: =_xlfn.IFNA(IF(I336<>0,VLOOKUP(I336,ItemText[],IFERROR(MATCH(UI!$B$1,ItemText[#Headers],0),2),FALSE),""),"Unset") -> 端正的光耀情景 | L336: =IF(VALUE(M336)=0,"",M336&"-"&N336) -> 6632600-透過潛在能力，能比較容易找到弩砲 | M336: 6632600 | N336: =IF(VALUE(M336)=0,"",VLOOKUP(VLOOKUP(M336,Tbl_Effect[],3,FALSE),EffectName[],IFERROR(MATCH(UI!$B$1,EffectName[#Headers],0),2),FALSE)) -> 透過潛在能力，能比較容易找到弩砲 | O336: =IF(VALUE(P336)=0,"",P336&"-"&Q336) -> 6632900-透過潛在能力，能比較容易找到大盾 | P336: 6632900 | Q336: =IF(VALUE(P336)=0,"",VLOOKUP(VLOOKUP(P336,Tbl_Effect[],3,FALSE),EffectName[],IFERROR(MATCH(UI!$B$1,EffectName[#Headers],0),2),FALSE)) -> 透過潛在能力，能比較容易找到大盾 | R336: =IF(VALUE(S336)=0,"",S336&"-"&T336) -> #N/A | S336: #N/A | T336: =IF(VALUE(S336)=0,"",VLOOKUP(VLOOKUP(S336,Tbl_Effect[],3,FALSE),EffectName[],IFERROR(MATCH(UI!$B$1,EffectName[#Headers],0),2),FALSE)) -> #N/A | U336: =IF(VALUE(V336)=0,"",V336&"-"&W336) | V336: 0 | W336: =IF(V336<>0,VLOOKUP(VLOOKUP(V336,Tbl_Effect[],3,FALSE),EffectName[],IFERROR(MATCH(UI!$B$1,EffectName[#Headers],0),2),FALSE),"") | X336: =IF(VALUE(Y336)=0,"",Y336&"-"&Z336) | Y336: 0 | Z336: =IF(Y336<>0,VLOOKUP(VLOOKUP(Y336,Tbl_Effect[],3,FALSE),EffectName[],IFERROR(MATCH(UI!$B$1,EffectName[#Headers],0),2),FALSE),"") | AA336: =IF(VALUE(AB336)=0,"",AB336&"-"&AC336) | AB336: 0 | AC336: =IF(AB336<>0,VLOOKUP(VLOOKUP(AB336,Tbl_Effect[],3,FALSE),EffectName[],IFERROR(MATCH(UI!$B$1,EffectName[#Headers],0),2),FALSE),"") | AE336: 6632600 | AF336: 6632900 | AG336: #N/A
H337: =IF(VALUE(I337)<>0,I337&"-"&K337&" ("&J337&")","") -> 1001222-遼闊的光耀情景 (黃) | I337: 1001222 | J337: =_xlfn.IFNA(IF(I337<>0,VLOOKUP(VLOOKUP(I337,Tbl_Equip[],2,FALSE),Tbl_Color[],IFERROR(MATCH(UI!$B$1,Tbl_Color[#Headers],0),2),FALSE),""),"Unset") -> 黃 | K337: =_xlfn.IFNA(IF(I337<>0,VLOOKUP(I337,ItemText[],IFERROR(MATCH(UI!$B$1,ItemText[#Headers],0),2),FALSE),""),"Unset") -> 遼闊的光耀情景 | L337: =IF(VALUE(M337)=0,"",M337&"-"&N337) -> 6632700-透過潛在能力，能比較容易找到小盾 | M337: 6632700 | N337: =IF(VALUE(M337)=0,"",VLOOKUP(VLOOKUP(M337,Tbl_Effect[],3,FALSE),EffectName[],IFERROR(MATCH(UI!$B$1,EffectName[#Headers],0),2),FALSE)) -> 透過潛在能力，能比較容易找到小盾 | O337: =IF(VALUE(P337)=0,"",P337&"-"&Q337) -> 6633000-透過潛在能力，能比較容易找到手杖 | P337: 6633000 | Q337: =IF(VALUE(P337)=0,"",VLOOKUP(VLOOKUP(P337,Tbl_Effect[],3,FALSE),EffectName[],IFERROR(MATCH(UI!$B$1,EffectName[#Headers],0),2),FALSE)) -> 透過潛在能力，能比較容易找到手杖 | R337: =IF(VALUE(S337)=0,"",S337&"-"&T337) -> #N/A | S337: #N/A | T337: =IF(VALUE(S337)=0,"",VLOOKUP(VLOOKUP(S337,Tbl_Effect[],3,FALSE),EffectName[],IFERROR(MATCH(UI!$B$1,EffectName[#Headers],0),2),FALSE)) -> #N/A | U337: =IF(VALUE(V337)=0,"",V337&"-"&W337) | V337: 0 | W337: =IF(V337<>0,VLOOKUP(VLOOKUP(V337,Tbl_Effect[],3,FALSE),EffectName[],IFERROR(MATCH(UI!$B$1,EffectName[#Headers],0),2),FALSE),"") | X337: =IF(VALUE(Y337)=0,"",Y337&"-"&Z337) | Y337: 0 | Z337: =IF(Y337<>0,VLOOKUP(VLOOKUP(Y337,Tbl_Effect[],3,FALSE),EffectName[],IFERROR(MATCH(UI!$B$1,EffectName[#Headers],0),2),FALSE),"") | AA337: =IF(VALUE(AB337)=0,"",AB337&"-"&AC337) | AB337: 0 | AC337: =IF(AB337<>0,VLOOKUP(VLOOKUP(AB337,Tbl_Effect[],3,FALSE),EffectName[],IFERROR(MATCH(UI!$B$1,EffectName[#Headers],0),2),FALSE),"") | AE337: 6632700 | AF337: 6633000 | AG337: #N/A
H338: =IF(VALUE(I338)<>0,I338&"-"&K338&" ("&J338&")","") -> 1001300-細膩的幽靜情景 (綠) | I338: 1001300 | J338: =_xlfn.IFNA(IF(I338<>0,VLOOKUP(VLOOKUP(I338,Tbl_Equip[],2,FALSE),Tbl_Color[],IFERROR(MATCH(UI!$B$1,Tbl_Color[#Headers],0),2),FALSE),""),"Unset") -> 綠 | K338: =_xlfn.IFNA(IF(I338<>0,VLOOKUP(I338,ItemText[],IFERROR(MATCH(UI!$B$1,ItemText[#Headers],0),2),FALSE),""),"Unset") -> 細膩的幽靜情景 | L338: =IF(VALUE(M338)=0,"",M338&"-"&N338) -> 6632800-透過潛在能力，能比較容易找到中盾 | M338: 6632800 | N338: =IF(VALUE(M338)=0,"",VLOOKUP(VLOOKUP(M338,Tbl_Effect[],3,FALSE),EffectName[],IFERROR(MATCH(UI!$B$1,EffectName[#Headers],0),2),FALSE)) -> 透過潛在能力，能比較容易找到中盾 | O338: =IF(VALUE(P338)=0,"",P338&"-"&Q338) -> 6633100-透過潛在能力，能比較容易找到聖印記 | P338: 6633100 | Q338: =IF(VALUE(P338)=0,"",VLOOKUP(VLOOKUP(P338,Tbl_Effect[],3,FALSE),EffectName[],IFERROR(MATCH(UI!$B$1,EffectName[#Headers],0),2),FALSE)) -> 透過潛在能力，能比較容易找到聖印記 | R338: =IF(VALUE(S338)=0,"",S338&"-"&T338) -> #N/A | S338: #N/A | T338: =IF(VALUE(S338)=0,"",VLOOKUP(VLOOKUP(S338,Tbl_Effect[],3,FALSE),EffectName[],IFERROR(MATCH(UI!$B$1,EffectName[#Headers],0),2),FALSE)) -> #N/A | U338: =IF(VALUE(V338)=0,"",V338&"-"&W338) | V338: 0 | W338: =IF(V338<>0,VLOOKUP(VLOOKUP(V338,Tbl_Effect[],3,FALSE),EffectName[],IFERROR(MATCH(UI!$B$1,EffectName[#Headers],0),2),FALSE),"") | X338: =IF(VALUE(Y338)=0,"",Y338&"-"&Z338) | Y338: 0 | Z338: =IF(Y338<>0,VLOOKUP(VLOOKUP(Y338,Tbl_Effect[],3,FALSE),EffectName[],IFERROR(MATCH(UI!$B$1,EffectName[#Headers],0),2),FALSE),"") | AA338: =IF(VALUE(AB338)=0,"",AB338&"-"&AC338) | AB338: 0 | AC338: =IF(AB338<>0,VLOOKUP(VLOOKUP(AB338,Tbl_Effect[],3,FALSE),EffectName[],IFERROR(MATCH(UI!$B$1,EffectName[#Headers],0),2),FALSE),"") | AE338: 6632800 | AF338: 6633100 | AG338: #N/A
H339: =IF(VALUE(I339)<>0,I339&"-"&K339&" ("&J339&")","") -> 1001301-端正的幽靜情景 (綠) | I339: 1001301 | J339: =_xlfn.IFNA(IF(I339<>0,VLOOKUP(VLOOKUP(I339,Tbl_Equip[],2,FALSE),Tbl_Color[],IFERROR(MATCH(UI!$B$1,Tbl_Color[#Headers],0),2),FALSE),""),"Unset") -> 綠 | K339: =_xlfn.IFNA(IF(I339<>0,VLOOKUP(I339,ItemText[],IFERROR(MATCH(UI!$B$1,ItemText[#Headers],0),2),FALSE),""),"Unset") -> 端正的幽靜情景 | L339: =IF(VALUE(M339)=0,"",M339&"-"&N339) -> 6632900-透過潛在能力，能比較容易找到大盾 | M339: 6632900 | N339: =IF(VALUE(M339)=0,"",VLOOKUP(VLOOKUP(M339,Tbl_Effect[],3,FALSE),EffectName[],IFERROR(MATCH(UI!$B$1,EffectName[#Headers],0),2),FALSE)) -> 透過潛在能力，能比較容易找到大盾 | O339: =IF(VALUE(P339)=0,"",P339&"-"&Q339) -> 6633200-透過潛在能力，能比較容易找到火把 | P339: 6633200 | Q339: =IF(VALUE(P339)=0,"",VLOOKUP(VLOOKUP(P339,Tbl_Effect[],3,FALSE),EffectName[],IFERROR(MATCH(UI!$B$1,EffectName[#Headers],0),2),FALSE)) -> 透過潛在能力，能比較容易找到火把 | R339: =IF(VALUE(S339)=0,"",S339&"-"&T339) -> #N/A | S339: #N/A | T339: =IF(VALUE(S339)=0,"",VLOOKUP(VLOOKUP(S339,Tbl_Effect[],3,FALSE),EffectName[],IFERROR(MATCH(UI!$B$1,EffectName[#Headers],0),2),FALSE)) -> #N/A | U339: =IF(VALUE(V339)=0,"",V339&"-"&W339) | V339: 0 | W339: =IF(V339<>0,VLOOKUP(VLOOKUP(V339,Tbl_Effect[],3,FALSE),EffectName[],IFERROR(MATCH(UI!$B$1,EffectName[#Headers],0),2),FALSE),"") | X339: =IF(VALUE(Y339)=0,"",Y339&"-"&Z339) | Y339: 0 | Z339: =IF(Y339<>0,VLOOKUP(VLOOKUP(Y339,Tbl_Effect[],3,FALSE),EffectName[],IFERROR(MATCH(UI!$B$1,EffectName[#Headers],0),2),FALSE),"") | AA339: =IF(VALUE(AB339)=0,"",AB339&"-"&AC339) | AB339: 0 | AC339: =IF(AB339<>0,VLOOKUP(VLOOKUP(AB339,Tbl_Effect[],3,FALSE),EffectName[],IFERROR(MATCH(UI!$B$1,EffectName[#Headers],0),2),FALSE),"") | AE339: 6632900 | AF339: 6633200 | AG339: #N/A
H340: =IF(VALUE(I340)<>0,I340&"-"&K340&" ("&J340&")","") -> 1001302-遼闊的幽靜情景 (綠) | I340: 1001302 | J340: =_xlfn.IFNA(IF(I340<>0,VLOOKUP(VLOOKUP(I340,Tbl_Equip[],2,FALSE),Tbl_Color[],IFERROR(MATCH(UI!$B$1,Tbl_Color[#Headers],0),2),FALSE),""),"Unset") -> 綠 | K340: =_xlfn.IFNA(IF(I340<>0,VLOOKUP(I340,ItemText[],IFERROR(MATCH(UI!$B$1,ItemText[#Headers],0),2),FALSE),""),"Unset") -> 遼闊的幽靜情景 | L340: =IF(VALUE(M340)=0,"",M340&"-"&N340) -> 6633000-透過潛在能力，能比較容易找到手杖 | M340: 6633000 | N340: =IF(VALUE(M340)=0,"",VLOOKUP(VLOOKUP(M340,Tbl_Effect[],3,FALSE),EffectName[],IFERROR(MATCH(UI!$B$1,EffectName[#Headers],0),2),FALSE)) -> 透過潛在能力，能比較容易找到手杖 | O340: =IF(VALUE(P340)=0,"",P340&"-"&Q340) -> 6647200-【學者】提升集中力，但降低生命力 | P340: 6647200 | Q340: =IF(VALUE(P340)=0,"",VLOOKUP(VLOOKUP(P340,Tbl_Effect[],3,FALSE),EffectName[],IFERROR(MATCH(UI!$B$1,EffectName[#Headers],0),2),FALSE)) -> 【學者】提升集中力，但降低生命力 | R340: =IF(VALUE(S340)=0,"",S340&"-"&T340) -> #N/A | S340: #N/A | T340: =IF(VALUE(S340)=0,"",VLOOKUP(VLOOKUP(S340,Tbl_Effect[],3,FALSE),EffectName[],IFERROR(MATCH(UI!$B$1,EffectName[#Headers],0),2),FALSE)) -> #N/A | U340: =IF(VALUE(V340)=0,"",V340&"-"&W340) | V340: 0 | W340: =IF(V340<>0,VLOOKUP(VLOOKUP(V340,Tbl_Effect[],3,FALSE),EffectName[],IFERROR(MATCH(UI!$B$1,EffectName[#Headers],0),2),FALSE),"") | X340: =IF(VALUE(Y340)=0,"",Y340&"-"&Z340) | Y340: 0 | Z340: =IF(Y340<>0,VLOOKUP(VLOOKUP(Y340,Tbl_Effect[],3,FALSE),EffectName[],IFERROR(MATCH(UI!$B$1,EffectName[#Headers],0),2),FALSE),"") | AA340: =IF(VALUE(AB340)=0,"",AB340&"-"&AC340) | AB340: 0 | AC340: =IF(AB340<>0,VLOOKUP(VLOOKUP(AB340,Tbl_Effect[],3,FALSE),EffectName[],IFERROR(MATCH(UI!$B$1,EffectName[#Headers],0),2),FALSE),"") | AE340: 6633000 | AF340: 6647200 | AG340: #N/A
H341: =IF(VALUE(I341)<>0,I341&"-"&K341&" ("&J341&")","") -> 1001310-細膩的幽靜情景 (綠) | I341: 1001310 | J341: =_xlfn.IFNA(IF(I341<>0,VLOOKUP(VLOOKUP(I341,Tbl_Equip[],2,FALSE),Tbl_Color[],IFERROR(MATCH(UI!$B$1,Tbl_Color[#Headers],0),2),FALSE),""),"Unset") -> 綠 | K341: =_xlfn.IFNA(IF(I341<>0,VLOOKUP(I341,ItemText[],IFERROR(MATCH(UI!$B$1,ItemText[#Headers],0),2),FALSE),""),"Unset") -> 細膩的幽靜情景 | L341: =IF(VALUE(M341)=0,"",M341&"-"&N341) -> 6633100-透過潛在能力，能比較容易找到聖印記 | M341: 6633100 | N341: =IF(VALUE(M341)=0,"",VLOOKUP(VLOOKUP(M341,Tbl_Effect[],3,FALSE),EffectName[],IFERROR(MATCH(UI!$B$1,EffectName[#Headers],0),2),FALSE)) -> 透過潛在能力，能比較容易找到聖印記 | O341: =IF(VALUE(P341)=0,"",P341&"-"&Q341) -> 6647300-【學者】提升耐力、靈巧，但降低智力、感應 | P341: 6647300 | Q341: =IF(VALUE(P341)=0,"",VLOOKUP(VLOOKUP(P341,Tbl_Effect[],3,FALSE),EffectName[],IFERROR(MATCH(UI!$B$1,EffectName[#Headers],0),2),FALSE)) -> 【學者】提升耐力、靈巧，但降低智力、感應 | R341: =IF(VALUE(S341)=0,"",S341&"-"&T341) -> #N/A | S341: #N/A | T341: =IF(VALUE(S341)=0,"",VLOOKUP(VLOOKUP(S341,Tbl_Effect[],3,FALSE),EffectName[],IFERROR(MATCH(UI!$B$1,EffectName[#Headers],0),2),FALSE)) -> #N/A | U341: =IF(VALUE(V341)=0,"",V341&"-"&W341) | V341: 0 | W341: =IF(V341<>0,VLOOKUP(VLOOKUP(V341,Tbl_Effect[],3,FALSE),EffectName[],IFERROR(MATCH(UI!$B$1,EffectName[#Headers],0),2),FALSE),"") | X341: =IF(VALUE(Y341)=0,"",Y341&"-"&Z341) | Y341: 0 | Z341: =IF(Y341<>0,VLOOKUP(VLOOKUP(Y341,Tbl_Effect[],3,FALSE),EffectName[],IFERROR(MATCH(UI!$B$1,EffectName[#Headers],0),2),FALSE),"") | AA341: =IF(VALUE(AB341)=0,"",AB341&"-"&AC341) | AB341: 0 | AC341: =IF(AB341<>0,VLOOKUP(VLOOKUP(AB341,Tbl_Effect[],3,FALSE),EffectName[],IFERROR(MATCH(UI!$B$1,EffectName[#Headers],0),2),FALSE),"") | AE341: 6633100 | AF341: 6647300 | AG341: #N/A
H342: =IF(VALUE(I342)<>0,I342&"-"&K342&" ("&J342&")","") -> 1001311-端正的幽靜情景 (綠) | I342: 1001311 | J342: =_xlfn.IFNA(IF(I342<>0,VLOOKUP(VLOOKUP(I342,Tbl_Equip[],2,FALSE),Tbl_Color[],IFERROR(MATCH(UI!$B$1,Tbl_Color[#Headers],0),2),FALSE),""),"Unset") -> 綠 | K342: =_xlfn.IFNA(IF(I342<>0,VLOOKUP(I342,ItemText[],IFERROR(MATCH(UI!$B$1,ItemText[#Headers],0),2),FALSE),""),"Unset") -> 端正的幽靜情景 | L342: =IF(VALUE(M342)=0,"",M342&"-"&N342) -> 6633200-透過潛在能力，能比較容易找到火把 | M342: 6633200 | N342: =IF(VALUE(M342)=0,"",VLOOKUP(VLOOKUP(M342,Tbl_Effect[],3,FALSE),EffectName[],IFERROR(MATCH(UI!$B$1,EffectName[#Headers],0),2),FALSE)) -> 透過潛在能力，能比較容易找到火把 | O342: =IF(VALUE(P342)=0,"",P342&"-"&Q342) -> 6647400-【送葬者】提升靈巧，但降低生命力、信仰 | P342: 6647400 | Q342: =IF(VALUE(P342)=0,"",VLOOKUP(VLOOKUP(P342,Tbl_Effect[],3,FALSE),EffectName[],IFERROR(MATCH(UI!$B$1,EffectName[#Headers],0),2),FALSE)) -> 【送葬者】提升靈巧，但降低生命力、信仰 | R342: =IF(VALUE(S342)=0,"",S342&"-"&T342) -> #N/A | S342: #N/A | T342: =IF(VALUE(S342)=0,"",VLOOKUP(VLOOKUP(S342,Tbl_Effect[],3,FALSE),EffectName[],IFERROR(MATCH(UI!$B$1,EffectName[#Headers],0),2),FALSE)) -> #N/A | U342: =IF(VALUE(V342)=0,"",V342&"-"&W342) | V342: 0 | W342: =IF(V342<>0,VLOOKUP(VLOOKUP(V342,Tbl_Effect[],3,FALSE),EffectName[],IFERROR(MATCH(UI!$B$1,EffectName[#Headers],0),2),FALSE),"") | X342: =IF(VALUE(Y342)=0,"",Y342&"-"&Z342) | Y342: 0 | Z342: =IF(Y342<>0,VLOOKUP(VLOOKUP(Y342,Tbl_Effect[],3,FALSE),EffectName[],IFERROR(MATCH(UI!$B$1,EffectName[#Headers],0),2),FALSE),"") | AA342: =IF(VALUE(AB342)=0,"",AB342&"-"&AC342) | AB342: 0 | AC342: =IF(AB342<>0,VLOOKUP(VLOOKUP(AB342,Tbl_Effect[],3,FALSE),EffectName[],IFERROR(MATCH(UI!$B$1,EffectName[#Headers],0),2),FALSE),"") | AE342: 6633200 | AF342: 6647400 | AG342: #N/A
H343: =IF(VALUE(I343)<>0,I343&"-"&K343&" ("&J343&")","") -> 1001312-遼闊的幽靜情景 (綠) | I343: 1001312 | J343: =_xlfn.IFNA(IF(I343<>0,VLOOKUP(VLOOKUP(I343,Tbl_Equip[],2,FALSE),Tbl_Color[],IFERROR(MATCH(UI!$B$1,Tbl_Color[#Headers],0),2),FALSE),""),"Unset") -> 綠 | K343: =_xlfn.IFNA(IF(I343<>0,VLOOKUP(I343,ItemText[],IFERROR(MATCH(UI!$B$1,ItemText[#Headers],0),2),FALSE),""),"Unset") -> 遼闊的幽靜情景 | L343: =IF(VALUE(M343)=0,"",M343&"-"&N343) -> 6647200-【學者】提升集中力，但降低生命力 | M343: 6647200 | N343: =IF(VALUE(M343)=0,"",VLOOKUP(VLOOKUP(M343,Tbl_Effect[],3,FALSE),EffectName[],IFERROR(MATCH(UI!$B$1,EffectName[#Headers],0),2),FALSE)) -> 【學者】提升集中力，但降低生命力 | O343: =IF(VALUE(P343)=0,"",P343&"-"&Q343) -> 6647500-【送葬者】提升集中力、信仰，但降低力氣 | P343: 6647500 | Q343: =IF(VALUE(P343)=0,"",VLOOKUP(VLOOKUP(P343,Tbl_Effect[],3,FALSE),EffectName[],IFERROR(MATCH(UI!$B$1,EffectName[#Headers],0),2),FALSE)) -> 【送葬者】提升集中力、信仰，但降低力氣 | R343: =IF(VALUE(S343)=0,"",S343&"-"&T343) -> #N/A | S343: #N/A | T343: =IF(VALUE(S343)=0,"",VLOOKUP(VLOOKUP(S343,Tbl_Effect[],3,FALSE),EffectName[],IFERROR(MATCH(UI!$B$1,EffectName[#Headers],0),2),FALSE)) -> #N/A | U343: =IF(VALUE(V343)=0,"",V343&"-"&W343) | V343: 0 | W343: =IF(V343<>0,VLOOKUP(VLOOKUP(V343,Tbl_Effect[],3,FALSE),EffectName[],IFERROR(MATCH(UI!$B$1,EffectName[#Headers],0),2),FALSE),"") | X343: =IF(VALUE(Y343)=0,"",Y343&"-"&Z343) | Y343: 0 | Z343: =IF(Y343<>0,VLOOKUP(VLOOKUP(Y343,Tbl_Effect[],3,FALSE),EffectName[],IFERROR(MATCH(UI!$B$1,EffectName[#Headers],0),2),FALSE),"") | AA343: =IF(VALUE(AB343)=0,"",AB343&"-"&AC343) | AB343: 0 | AC343: =IF(AB343<>0,VLOOKUP(VLOOKUP(AB343,Tbl_Effect[],3,FALSE),EffectName[],IFERROR(MATCH(UI!$B$1,EffectName[#Headers],0),2),FALSE),"") | AE343: 6647200 | AF343: 6647500 | AG343: #N/A
H344: =IF(VALUE(I344)<>0,I344&"-"&K344&" ("&J344&")","") -> 1001320-細膩的幽靜情景 (綠) | I344: 1001320 | J344: =_xlfn.IFNA(IF(I344<>0,VLOOKUP(VLOOKUP(I344,Tbl_Equip[],2,FALSE),Tbl_Color[],IFERROR(MATCH(UI!$B$1,Tbl_Color[#Headers],0),2),FALSE),""),"Unset") -> 綠 | K344: =_xlfn.IFNA(IF(I344<>0,VLOOKUP(I344,ItemText[],IFERROR(MATCH(UI!$B$1,ItemText[#Headers],0),2),FALSE),""),"Unset") -> 細膩的幽靜情景 | L344: =IF(VALUE(M344)=0,"",M344&"-"&N344) -> 6647300-【學者】提升耐力、靈巧，但降低智力、感應 | M344: 6647300 | N344: =IF(VALUE(M344)=0,"",VLOOKUP(VLOOKUP(M344,Tbl_Effect[],3,FALSE),EffectName[],IFERROR(MATCH(UI!$B$1,EffectName[#Headers],0),2),FALSE)) -> 【學者】提升耐力、靈巧，但降低智力、感應 | O344: =IF(VALUE(P344)=0,"",P344&"-"&Q344) -> 6640000-【追蹤者】提升集中力，但降低生命力 | P344: 6640000 | Q344: =IF(VALUE(P344)=0,"",VLOOKUP(VLOOKUP(P344,Tbl_Effect[],3,FALSE),EffectName[],IFERROR(MATCH(UI!$B$1,EffectName[#Headers],0),2),FALSE)) -> 【追蹤者】提升集中力，但降低生命力 | R344: =IF(VALUE(S344)=0,"",S344&"-"&T344) -> #N/A | S344: #N/A | T344: =IF(VALUE(S344)=0,"",VLOOKUP(VLOOKUP(S344,Tbl_Effect[],3,FALSE),EffectName[],IFERROR(MATCH(UI!$B$1,EffectName[#Headers],0),2),FALSE)) -> #N/A | U344: =IF(VALUE(V344)=0,"",V344&"-"&W344) | V344: 0 | W344: =IF(V344<>0,VLOOKUP(VLOOKUP(V344,Tbl_Effect[],3,FALSE),EffectName[],IFERROR(MATCH(UI!$B$1,EffectName[#Headers],0),2),FALSE),"") | X344: =IF(VALUE(Y344)=0,"",Y344&"-"&Z344) | Y344: 0 | Z344: =IF(Y344<>0,VLOOKUP(VLOOKUP(Y344,Tbl_Effect[],3,FALSE),EffectName[],IFERROR(MATCH(UI!$B$1,EffectName[#Headers],0),2),FALSE),"") | AA344: =IF(VALUE(AB344)=0,"",AB344&"-"&AC344) | AB344: 0 | AC344: =IF(AB344<>0,VLOOKUP(VLOOKUP(AB344,Tbl_Effect[],3,FALSE),EffectName[],IFERROR(MATCH(UI!$B$1,EffectName[#Headers],0),2),FALSE),"") | AE344: 6647300 | AF344: 6640000 | AG344: #N/A
H345: =IF(VALUE(I345)<>0,I345&"-"&K345&" ("&J345&")","") -> 1001321-端正的幽靜情景 (綠) | I345: 1001321 | J345: =_xlfn.IFNA(IF(I345<>0,VLOOKUP(VLOOKUP(I345,Tbl_Equip[],2,FALSE),Tbl_Color[],IFERROR(MATCH(UI!$B$1,Tbl_Color[#Headers],0),2),FALSE),""),"Unset") -> 綠 | K345: =_xlfn.IFNA(IF(I345<>0,VLOOKUP(I345,ItemText[],IFERROR(MATCH(UI!$B$1,ItemText[#Headers],0),2),FALSE),""),"Unset") -> 端正的幽靜情景 | L345: =IF(VALUE(M345)=0,"",M345&"-"&N345) -> 6647400-【送葬者】提升靈巧，但降低生命力、信仰 | M345: 6647400 | N345: =IF(VALUE(M345)=0,"",VLOOKUP(VLOOKUP(M345,Tbl_Effect[],3,FALSE),EffectName[],IFERROR(MATCH(UI!$B$1,EffectName[#Headers],0),2),FALSE)) -> 【送葬者】提升靈巧，但降低生命力、信仰 | O345: =IF(VALUE(P345)=0,"",P345&"-"&Q345) -> 6640100-【追蹤者】提升智力、信仰，但降低力氣、靈巧 | P345: 6640100 | Q345: =IF(VALUE(P345)=0,"",VLOOKUP(VLOOKUP(P345,Tbl_Effect[],3,FALSE),EffectName[],IFERROR(MATCH(UI!$B$1,EffectName[#Headers],0),2),FALSE)) -> 【追蹤者】提升智力、信仰，但降低力氣、靈巧 | R345: =IF(VALUE(S345)=0,"",S345&"-"&T345) -> #N/A | S345: #N/A | T345: =IF(VALUE(S345)=0,"",VLOOKUP(VLOOKUP(S345,Tbl_Effect[],3,FALSE),EffectName[],IFERROR(MATCH(UI!$B$1,EffectName[#Headers],0),2),FALSE)) -> #N/A | U345: =IF(VALUE(V345)=0,"",V345&"-"&W345) | V345: 0 | W345: =IF(V345<>0,VLOOKUP(VLOOKUP(V345,Tbl_Effect[],3,FALSE),EffectName[],IFERROR(MATCH(UI!$B$1,EffectName[#Headers],0),2),FALSE),"") | X345: =IF(VALUE(Y345)=0,"",Y345&"-"&Z345) | Y345: 0 | Z345: =IF(Y345<>0,VLOOKUP(VLOOKUP(Y345,Tbl_Effect[],3,FALSE),EffectName[],IFERROR(MATCH(UI!$B$1,EffectName[#Headers],0),2),FALSE),"") | AA345: =IF(VALUE(AB345)=0,"",AB345&"-"&AC345) | AB345: 0 | AC345: =IF(AB345<>0,VLOOKUP(VLOOKUP(AB345,Tbl_Effect[],3,FALSE),EffectName[],IFERROR(MATCH(UI!$B$1,EffectName[#Headers],0),2),FALSE),"") | AE345: 6647400 | AF345: 6640100 | AG345: #N/A
H346: =IF(VALUE(I346)<>0,I346&"-"&K346&" ("&J346&")","") -> 1001322-遼闊的幽靜情景 (綠) | I346: 1001322 | J346: =_xlfn.IFNA(IF(I346<>0,VLOOKUP(VLOOKUP(I346,Tbl_Equip[],2,FALSE),Tbl_Color[],IFERROR(MATCH(UI!$B$1,Tbl_Color[#Headers],0),2),FALSE),""),"Unset") -> 綠 | K346: =_xlfn.IFNA(IF(I346<>0,VLOOKUP(I346,ItemText[],IFERROR(MATCH(UI!$B$1,ItemText[#Headers],0),2),FALSE),""),"Unset") -> 遼闊的幽靜情景 | L346: =IF(VALUE(M346)=0,"",M346&"-"&N346) -> 6647500-【送葬者】提升集中力、信仰，但降低力氣 | M346: 6647500 | N346: =IF(VALUE(M346)=0,"",VLOOKUP(VLOOKUP(M346,Tbl_Effect[],3,FALSE),EffectName[],IFERROR(MATCH(UI!$B$1,EffectName[#Headers],0),2),FALSE)) -> 【送葬者】提升集中力、信仰，但降低力氣 | O346: =IF(VALUE(P346)=0,"",P346&"-"&Q346) -> 6641000-【守護者】提升力氣、靈巧，但降低生命力 | P346: 6641000 | Q346: =IF(VALUE(P346)=0,"",VLOOKUP(VLOOKUP(P346,Tbl_Effect[],3,FALSE),EffectName[],IFERROR(MATCH(UI!$B$1,EffectName[#Headers],0),2),FALSE)) -> 【守護者】提升力氣、靈巧，但降低生命力 | R346: =IF(VALUE(S346)=0,"",S346&"-"&T346) -> #N/A | S346: #N/A | T346: =IF(VALUE(S346)=0,"",VLOOKUP(VLOOKUP(S346,Tbl_Effect[],3,FALSE),EffectName[],IFERROR(MATCH(UI!$B$1,EffectName[#Headers],0),2),FALSE)) -> #N/A | U346: =IF(VALUE(V346)=0,"",V346&"-"&W346) | V346: 0 | W346: =IF(V346<>0,VLOOKUP(VLOOKUP(V346,Tbl_Effect[],3,FALSE),EffectName[],IFERROR(MATCH(UI!$B$1,EffectName[#Headers],0),2),FALSE),"") | X346: =IF(VALUE(Y346)=0,"",Y346&"-"&Z346) | Y346: 0 | Z346: =IF(Y346<>0,VLOOKUP(VLOOKUP(Y346,Tbl_Effect[],3,FALSE),EffectName[],IFERROR(MATCH(UI!$B$1,EffectName[#Headers],0),2),FALSE),"") | AA346: =IF(VALUE(AB346)=0,"",AB346&"-"&AC346) | AB346: 0 | AC346: =IF(AB346<>0,VLOOKUP(VLOOKUP(AB346,Tbl_Effect[],3,FALSE),EffectName[],IFERROR(MATCH(UI!$B$1,EffectName[#Headers],0),2),FALSE),"") | AE346: 6647500 | AF346: 6641000 | AG346: #N/A
H347: =IF(VALUE(I347)<>0,I347&"-"&K347&" ("&J347&")","") -> 1002000-細膩的火燃情景 (紅) | I347: 1002000 | J347: =_xlfn.IFNA(IF(I347<>0,VLOOKUP(VLOOKUP(I347,Tbl_Equip[],2,FALSE),Tbl_Color[],IFERROR(MATCH(UI!$B$1,Tbl_Color[#Headers],0),2),FALSE),""),"Unset") -> 紅 | K347: =_xlfn.IFNA(IF(I347<>0,VLOOKUP(I347,ItemText[],IFERROR(MATCH(UI!$B$1,ItemText[#Headers],0),2),FALSE),""),"Unset") -> 細膩的火燃情景 | L347: =IF(VALUE(M347)=0,"",M347&"-"&N347) -> 6640000-【追蹤者】提升集中力，但降低生命力 | M347: 6640000 | N347: =IF(VALUE(M347)=0,"",VLOOKUP(VLOOKUP(M347,Tbl_Effect[],3,FALSE),EffectName[],IFERROR(MATCH(UI!$B$1,EffectName[#Headers],0),2),FALSE)) -> 【追蹤者】提升集中力，但降低生命力 | O347: =IF(VALUE(P347)=0,"",P347&"-"&Q347) -> 6641100-【守護者】提升集中力、信仰，但降低生命力 | P347: 6641100 | Q347: =IF(VALUE(P347)=0,"",VLOOKUP(VLOOKUP(P347,Tbl_Effect[],3,FALSE),EffectName[],IFERROR(MATCH(UI!$B$1,EffectName[#Headers],0),2),FALSE)) -> 【守護者】提升集中力、信仰，但降低生命力 | R347: =IF(VALUE(S347)=0,"",S347&"-"&T347) -> #N/A | S347: #N/A | T347: =IF(VALUE(S347)=0,"",VLOOKUP(VLOOKUP(S347,Tbl_Effect[],3,FALSE),EffectName[],IFERROR(MATCH(UI!$B$1,EffectName[#Headers],0),2),FALSE)) -> #N/A | U347: =IF(VALUE(V347)=0,"",V347&"-"&W347) | V347: 0 | W347: =IF(V347<>0,VLOOKUP(VLOOKUP(V347,Tbl_Effect[],3,FALSE),EffectName[],IFERROR(MATCH(UI!$B$1,EffectName[#Headers],0),2),FALSE),"") | X347: =IF(VALUE(Y347)=0,"",Y347&"-"&Z347) | Y347: 0 | Z347: =IF(Y347<>0,VLOOKUP(VLOOKUP(Y347,Tbl_Effect[],3,FALSE),EffectName[],IFERROR(MATCH(UI!$B$1,EffectName[#Headers],0),2),FALSE),"") | AA347: =IF(VALUE(AB347)=0,"",AB347&"-"&AC347) | AB347: 0 | AC347: =IF(AB347<>0,VLOOKUP(VLOOKUP(AB347,Tbl_Effect[],3,FALSE),EffectName[],IFERROR(MATCH(UI!$B$1,EffectName[#Headers],0),2),FALSE),"") | AE347: 6640000 | AF347: 6641100 | AG347: #N/A
... H359: =IF(VALUE(I359)<>0,I359&"-"&K359&" ("&J359&")","") -> 1002110-細膩的水滴情景 (藍) | I359: 1002110 | J359: =_xlfn.IFNA(IF(I359<>0,VLOOKUP(VLOOKUP(I359,Tbl_Equip[],2,FALSE),Tbl_Color[],IFERROR(MATCH(UI!$B$1,Tbl_Color[#Headers],0),2),FALSE),""),"Unset") -> 藍 | K359: =_xlfn.IFNA(IF(I359<>0,VLOOKUP(I359,ItemText[],IFERROR(MATCH(UI!$B$1,ItemText[#Headers],0),2),FALSE),""),"Unset") -> 細膩的水滴情景 | L359: =IF(VALUE(M359)=0,"",M359&"-"&N359) -> 6646000-【隱士】提升生命力、耐力、靈巧，但降低智力、信仰 | M359: 6646000 | N359: =IF(VALUE(M359)=0,"",VLOOKUP(VLOOKUP(M359,Tbl_Effect[],3,FALSE),EffectName[],IFERROR(MATCH(UI!$B$1,EffectName[#Headers],0),2),FALSE)) -> 【隱士】提升生命力、耐力、靈巧，但降低智力、信仰 | O359: =IF(VALUE(P359)=0,"",P359&"-"&Q359) -> 6647100-【執行者】提升靈巧、感應，但降低生命力 | P359: 6647100 | Q359: =IF(VALUE(P359)=0,"",VLOOKUP(VLOOKUP(P359,Tbl_Effect[],3,FALSE),EffectName[],IFERROR(MATCH(UI!$B$1,EffectName[#Headers],0),2),FALSE)) -> 【執行者】提升靈巧、感應，但降低生命力 | R359: =IF(VALUE(S359)=0,"",S359&"-"&T359) -> #N/A | S359: #N/A | T359: =IF(VALUE(S359)=0,"",VLOOKUP(VLOOKUP(S359,Tbl_Effect[],3,FALSE),EffectName[],IFERROR(MATCH(UI!$B$1,EffectName[#Headers],0),2),FALSE)) -> #N/A | U359: =IF(VALUE(V359)=0,"",V359&"-"&W359) | V359: 0 | W359: =IF(V359<>0,VLOOKUP(VLOOKUP(V359,Tbl_Effect[],3,FALSE),EffectName[],IFERROR(MATCH(UI!$B$1,EffectName[#Headers],0),2),FALSE),"") | X359: =IF(VALUE(Y359)=0,"",Y359&"-"&Z359) | Y359: 0 | Z359: =IF(Y359<>0,VLOOKUP(VLOOKUP(Y359,Tbl_Effect[],3,FALSE),EffectName[],IFERROR(MATCH(UI!$B$1,EffectName[#Headers],0),2),FALSE),"") | AA359: =IF(VALUE(AB359)=0,"",AB359&"-"&AC359) | AB359: 0 | AC359: =IF(AB359<>0,VLOOKUP(VLOOKUP(AB359,Tbl_Effect[],3,FALSE),EffectName[],IFERROR(MATCH(UI!$B$1,EffectName[#Headers],0),2),FALSE),"") | AE359: 6646000 | AF359: 6647100 | AG359: #N/A
